Workbook

Sheet EffFrontInputs
A2: # sectors (max 100) | B2: 13
B3: Apartment | C3: Industrial | D3: Office | E3: Retail | F3: Seniors | G3: Storage | H3: Life Science | I3: Hotel | J3: Student | K3: Medical Office | L3: Data Center | M3: SFR | N3: Manufactured
A4: expected_returns | B4: 0.065552443 | C4: 0.10138031 | D4: 0.03431678 | E4: 0.055641768 | F4: 0.099732922 | G4: 0.11256441 | H4: 0.09340312 | I4: 0.044260049 | J4: 0.059025678 | K4: 0.050263474 | L4: 0.097754626 | M4: 0.076541481 | N4: 0.090157905
A5: Annual_Volatility | B5: 0.084048468 | C5: 0.10959466 | D5: 0.12320215 | E5: 0.082179632 | F5: 0.079697376 | G5: 0.097438822 | H5: 0.1541738 | I5: 0.13237086 | J5: 0.097438822 | K5: 0.089113231 | L5: 0.061603622 | M5: 0.22680716 | N5: 0.078458687
B8: Apartment | C8: Industrial | D8: Office | E8: Retail | F8: Seniors | G8: Storage | H8: Life Science | I8: Hotel | J8: Student | K8: Medical Office | L8: Data Center | M8: SFR | N8: Manufactured
A9: Apartment | B9: 0.007064145 | C9: 0.007851763 | D9: 0.0085357734 | E9: 0.0049623101 | F9: 0.0027196365 | G9: 0.0045531987 | H9: 0.0071024148 | I9: 0.00046230569 | J9: 0.0038791356 | K9: 0.018155095 | L9: 0.0026504499 | M9: 0.0056805481 | N9: 0.0015681671 | V9: 0 | W9: 0 | X9: 0 | Y9: 0 | Z9: 0 | AA9: 0 | AB9: 0 | AC9: 0 | AD9: 0 | AE9: 0 | AF9: 0 | AG9: 0 | AH9: 0 | AI9: 0 | AJ9: 0 | AK9: 0 | AL9: 0 | AM9: 0 | AN9: 0 | AO9: 0 | AP9: 0 | AQ9: 0 | AR9: 0 | AS9: 0 | AT9: 0 | AU9: 0 | AV9: 0 | AW9: 0 | AX9: 0 | AY9: 0 | AZ9: 0 | BA9: 0 | BB9: 0 | BC9: 0 | BD9: 0 | BE9: 0 | BF9: 0 | BG9: 0 | BH9: 0 | BI9: 0 | BJ9: 0 | BK9: 0 | BL9: 0 | BM9: 0 | BN9: 0 | BO9: 0 | BP9: 0 | BQ9: 0 | BR9: 0 | BS9: 0 | BT9: 0 | BU9: 0 | BV9: 0 | BW9: 0 | BX9: 0 | BY9: 0 | BZ9: 0 | CA9: 0 | CB9: 0 | CC9: 0 | CD9: 0 | CE9: 0 | CF9: 0 | CG9: 0 | CH9: 0 | CI9: 0 | CJ9: 0 | CK9: 0 | CL9: 0 | CM9: 0 | CN9: 0 | CO9: 0 | CP9: 0 | CQ9: 0 | CR9: 0 | CS9: 0 | CT9: 0 | CU9: 0 | CV9: 0 | CW9: 0
A10: Industrial | B10: 0.007851763 | C10: 0.01201099 | D10: 0.010018157 | E10: 0.0055227877 | F10: 0.0049702057 | G10: 0.0059860244 | H10: 0.0088730471 | I10: -0.0013667762 | J10: 0.0051033043 | K10: 0.027272217 | L10: 0.0019597948 | M10: 0.0073110452 | N10: 0.0023317981 | V10: 0 | W10: 0 | X10: 0 | Y10: 0 | Z10: 0 | AA10: 0 | AB10: 0 | AC10: 0 | AD10: 0 | AE10: 0 | AF10: 0 | AG10: 0 | AH10: 0 | AI10: 0 | AJ10: 0 | AK10: 0 | AL10: 0 | AM10: 0 | AN10: 0 | AO10: 0 | AP10: 0 | AQ10: 0 | AR10: 0 | AS10: 0 | AT10: 0 | AU10: 0 | AV10: 0 | AW10: 0 | AX10: 0 | AY10: 0 | AZ10: 0 | BA10: 0 | BB10: 0 | BC10: 0 | BD10: 0 | BE10: 0 | BF10: 0 | BG10: 0 | BH10: 0 | BI10: 0 | BJ10: 0 | BK10: 0 | BL10: 0 | BM10: 0 | BN10: 0 | BO10: 0 | BP10: 0 | BQ10: 0 | BR10: 0 | BS10: 0 | BT10: 0 | BU10: 0 | BV10: 0 | BW10: 0 | BX10: 0 | BY10: 0 | BZ10: 0 | CA10: 0 | CB10: 0 | CC10: 0 | CD10: 0 | CE10: 0 | CF10: 0 | CG10: 0 | CH10: 0 | CI10: 0 | CJ10: 0 | CK10: 0 | CL10: 0 | CM10: 0 | CN10: 0 | CO10: 0 | CP10: 0 | CQ10: 0 | CR10: 0 | CS10: 0 | CT10: 0 | CU10: 0 | CV10: 0 | CW10: 0
A11: Office | B11: 0.0085357734 | C11: 0.010018157 | D11: 0.015178771 | E11: 0.0073510272 | F11: 0.00387677 | G11: 0.0090860404 | H11: 0.01192322 | I11: -0.0023767155 | J11: 0.0072373684 | K11: 0.011789752 | L11: 0.0044658519 | M11: 0.0073885304 | N11: 0.0016774693 | V11: 0 | W11: 0 | X11: 0 | Y11: 0 | Z11: 0 | AA11: 0 | AB11: 0 | AC11: 0 | AD11: 0 | AE11: 0 | AF11: 0 | AG11: 0 | AH11: 0 | AI11: 0 | AJ11: 0 | AK11: 0 | AL11: 0 | AM11: 0 | AN11: 0 | AO11: 0 | AP11: 0 | AQ11: 0 | AR11: 0 | AS11: 0 | AT11: 0 | AU11: 0 | AV11: 0 | AW11: 0 | AX11: 0 | AY11: 0 | AZ11: 0 | BA11: 0 | BB11: 0 | BC11: 0 | BD11: 0 | BE11: 0 | BF11: 0 | BG11: 0 | BH11: 0 | BI11: 0 | BJ11: 0 | BK11: 0 | BL11: 0 | BM11: 0 | BN11: 0 | BO11: 0 | BP11: 0 | BQ11: 0 | BR11: 0 | BS11: 0 | BT11: 0 | BU11: 0 | BV11: 0 | BW11: 0 | BX11: 0 | BY11: 0 | BZ11: 0 | CA11: 0 | CB11: 0 | CC11: 0 | CD11: 0 | CE11: 0 | CF11: 0 | CG11: 0 | CH11: 0 | CI11: 0 | CJ11: 0 | CK11: 0 | CL11: 0 | CM11: 0 | CN11: 0 | CO11: 0 | CP11: 0 | CQ11: 0 | CR11: 0 | CS11: 0 | CT11: 0 | CU11: 0 | CV11: 0 | CW11: 0
A12: Retail | B12: 0.0049623101 | C12: 0.0055227877 | D12: 0.0073510272 | E12: 0.006753492 | F12: 0.0019150966 | G12: 0.0057577756 | H12: 0.0045886265 | I12: -0.00041258292 | J12: 0.0030545714 | K12: 0.0064709919 | L12: 0.002807566 | M12: 0.0040811974 | N12: 0.0014471843 | V12: 0 | W12: 0 | X12: 0 | Y12: 0 | Z12: 0 | AA12: 0 | AB12: 0 | AC12: 0 | AD12: 0 | AE12: 0 | AF12: 0 | AG12: 0 | AH12: 0 | AI12: 0 | AJ12: 0 | AK12: 0 | AL12: 0 | AM12: 0 | AN12: 0 | AO12: 0 | AP12: 0 | AQ12: 0 | AR12: 0 | AS12: 0 | AT12: 0 | AU12: 0 | AV12: 0 | AW12: 0 | AX12: 0 | AY12: 0 | AZ12: 0 | BA12: 0 | BB12: 0 | BC12: 0 | BD12: 0 | BE12: 0 | BF12: 0 | BG12: 0 | BH12: 0 | BI12: 0 | BJ12: 0 | BK12: 0 | BL12: 0 | BM12: 0 | BN12: 0 | BO12: 0 | BP12: 0 | BQ12: 0 | BR12: 0 | BS12: 0 | BT12: 0 | BU12: 0 | BV12: 0 | BW12: 0 | BX12: 0 | BY12: 0 | BZ12: 0 | CA12: 0 | CB12: 0 | CC12: 0 | CD12: 0 | CE12: 0 | CF12: 0 | CG12: 0 | CH12: 0 | CI12: 0 | CJ12: 0 | CK12: 0 | CL12: 0 | CM12: 0 | CN12: 0 | CO12: 0 | CP12: 0 | CQ12: 0 | CR12: 0 | CS12: 0 | CT12: 0 | CU12: 0 | CV12: 0 | CW12: 0
A13: Seniors | B13: 0.0027196365 | C13: 0.0049702057 | D13: 0.00387677 | E13: 0.0019150966 | F13: 0.0037950063 | G13: 0.00055901584 | H13: 0.0027234563 | I13: 0.00016463137 | J13: 0.0015169414 | K13: 0.00075012682 | L13: 0.00064461816 | M13: 0.0020725215 | N13: 0.00039534565 | V13: 0 | W13: 0 | X13: 0 | Y13: 0 | Z13: 0 | AA13: 0 | AB13: 0 | AC13: 0 | AD13: 0 | AE13: 0 | AF13: 0 | AG13: 0 | AH13: 0 | AI13: 0 | AJ13: 0 | AK13: 0 | AL13: 0 | AM13: 0 | AN13: 0 | AO13: 0 | AP13: 0 | AQ13: 0 | AR13: 0 | AS13: 0 | AT13: 0 | AU13: 0 | AV13: 0 | AW13: 0 | AX13: 0 | AY13: 0 | AZ13: 0 | BA13: 0 | BB13: 0 | BC13: 0 | BD13: 0 | BE13: 0 | BF13: 0 | BG13: 0 | BH13: 0 | BI13: 0 | BJ13: 0 | BK13: 0 | BL13: 0 | BM13: 0 | BN13: 0 | BO13: 0 | BP13: 0 | BQ13: 0 | BR13: 0 | BS13: 0 | BT13: 0 | BU13: 0 | BV13: 0 | BW13: 0 | BX13: 0 | BY13: 0 | BZ13: 0 | CA13: 0 | CB13: 0 | CC13: 0 | CD13: 0 | CE13: 0 | CF13: 0 | CG13: 0 | CH13: 0 | CI13: 0 | CJ13: 0 | CK13: 0 | CL13: 0 | CM13: 0 | CN13: 0 | CO13: 0 | CP13: 0 | CQ13: 0 | CR13: 0 | CS13: 0 | CT13: 0 | CU13: 0 | CV13: 0 | CW13: 0
A14: Storage | B14: 0.0045531987 | C14: 0.0059860244 | D14: 0.0090860404 | E14: 0.0057577756 | F14: 0.00055901584 | G14: 0.017522045 | H14: 0.010078023 | I14: 0.00029746545 | J14: 0.0069534921 | K14: 0.0044843358 | L14: 0.0031605184 | M14: 0.0046451498 | N14: 0.0016129045 | V14: 0 | W14: 0 | X14: 0 | Y14: 0 | Z14: 0 | AA14: 0 | AB14: 0 | AC14: 0 | AD14: 0 | AE14: 0 | AF14: 0 | AG14: 0 | AH14: 0 | AI14: 0 | AJ14: 0 | AK14: 0 | AL14: 0 | AM14: 0 | AN14: 0 | AO14: 0 | AP14: 0 | AQ14: 0 | AR14: 0 | AS14: 0 | AT14: 0 | AU14: 0 | AV14: 0 | AW14: 0 | AX14: 0 | AY14: 0 | AZ14: 0 | BA14: 0 | BB14: 0 | BC14: 0 | BD14: 0 | BE14: 0 | BF14: 0 | BG14: 0 | BH14: 0 | BI14: 0 | BJ14: 0 | BK14: 0 | BL14: 0 | BM14: 0 | BN14: 0 | BO14: 0 | BP14: 0 | BQ14: 0 | BR14: 0 | BS14: 0 | BT14: 0 | BU14: 0 | BV14: 0 | BW14: 0 | BX14: 0 | BY14: 0 | BZ14: 0 | CA14: 0 | CB14: 0 | CC14: 0 | CD14: 0 | CE14: 0 | CF14: 0 | CG14: 0 | CH14: 0 | CI14: 0 | CJ14: 0 | CK14: 0 | CL14: 0 | CM14: 0 | CN14: 0 | CO14: 0 | CP14: 0 | CQ14: 0 | CR14: 0 | CS14: 0 | CT14: 0 | CU14: 0 | CV14: 0 | CW14: 0
A15: Life Science | B15: 0.0071024148 | C15: 0.0088730471 | D15: 0.01192322 | E15: 0.0045886265 | F15: 0.0027234563 | G15: 0.010078023 | H15: 0.023769561 | I15: 0.00011728729 | J15: 0.0056350079 | K15: 0.014649818 | L15: 0.0043931368 | M15: 0.0071680878 | N15: 0.00075940623 | V15: 0 | W15: 0 | X15: 0 | Y15: 0 | Z15: 0 | AA15: 0 | AB15: 0 | AC15: 0 | AD15: 0 | AE15: 0 | AF15: 0 | AG15: 0 | AH15: 0 | AI15: 0 | AJ15: 0 | AK15: 0 | AL15: 0 | AM15: 0 | AN15: 0 | AO15: 0 | AP15: 0 | AQ15: 0 | AR15: 0 | AS15: 0 | AT15: 0 | AU15: 0 | AV15: 0 | AW15: 0 | AX15: 0 | AY15: 0 | AZ15: 0 | BA15: 0 | BB15: 0 | BC15: 0 | BD15: 0 | BE15: 0 | BF15: 0 | BG15: 0 | BH15: 0 | BI15: 0 | BJ15: 0 | BK15: 0 | BL15: 0 | BM15: 0 | BN15: 0 | BO15: 0 | BP15: 0 | BQ15: 0 | BR15: 0 | BS15: 0 | BT15: 0 | BU15: 0 | BV15: 0 | BW15: 0 | BX15: 0 | BY15: 0 | BZ15: 0 | CA15: 0 | CB15: 0 | CC15: 0 | CD15: 0 | CE15: 0 | CF15: 0 | CG15: 0 | CH15: 0 | CI15: 0 | CJ15: 0 | CK15: 0 | CL15: 0 | CM15: 0 | CN15: 0 | CO15: 0 | CP15: 0 | CQ15: 0 | CR15: 0 | CS15: 0 | CT15: 0 | CU15: 0 | CV15: 0 | CW15: 0
A16: Hotel | B16: 0.00046230569 | C16: -0.0013667762 | D16: -0.0023767155 | E16: -0.00041258292 | F16: 0.00016463137 | G16: 0.00029746545 | H16: 0.00011728729 | I16: 0.0061557656 | J16: 0.00033006543 | K16: 0.0014256544 | L16: 0.00043174459 | M16: 0.00088970069 | N16: -0.00016514137 | V16: 0 | W16: 0 | X16: 0 | Y16: 0 | Z16: 0 | AA16: 0 | AB16: 0 | AC16: 0 | AD16: 0 | AE16: 0 | AF16: 0 | AG16: 0 | AH16: 0 | AI16: 0 | AJ16: 0 | AK16: 0 | AL16: 0 | AM16: 0 | AN16: 0 | AO16: 0 | AP16: 0 | AQ16: 0 | AR16: 0 | AS16: 0 | AT16: 0 | AU16: 0 | AV16: 0 | AW16: 0 | AX16: 0 | AY16: 0 | AZ16: 0 | BA16: 0 | BB16: 0 | BC16: 0 | BD16: 0 | BE16: 0 | BF16: 0 | BG16: 0 | BH16: 0 | BI16: 0 | BJ16: 0 | BK16: 0 | BL16: 0 | BM16: 0 | BN16: 0 | BO16: 0 | BP16: 0 | BQ16: 0 | BR16: 0 | BS16: 0 | BT16: 0 | BU16: 0 | BV16: 0 | BW16: 0 | BX16: 0 | BY16: 0 | BZ16: 0 | CA16: 0 | CB16: 0 | CC16: 0 | CD16: 0 | CE16: 0 | CF16: 0 | CG16: 0 | CH16: 0 | CI16: 0 | CJ16: 0 | CK16: 0 | CL16: 0 | CM16: 0 | CN16: 0 | CO16: 0 | CP16: 0 | CQ16: 0 | CR16: 0 | CS16: 0 | CT16: 0 | CU16: 0 | CV16: 0 | CW16: 0
A17: Student | B17: 0.0038791356 | C17: 0.0051033043 | D17: 0.0072373684 | E17: 0.0030545714 | F17: 0.0015169414 | G17: 0.0069534921 | H17: 0.0056350079 | I17: 0.00033006543 | J17: 0.007941168 | K17: 0.0061234947 | L17: 0.0013444289 | M17: 0.0032672045 | N17: 0.00095671305 | V17: 0 | W17: 0 | X17: 0 | Y17: 0 | Z17: 0 | AA17: 0 | AB17: 0 | AC17: 0 | AD17: 0 | AE17: 0 | AF17: 0 | AG17: 0 | AH17: 0 | AI17: 0 | AJ17: 0 | AK17: 0 | AL17: 0 | AM17: 0 | AN17: 0 | AO17: 0 | AP17: 0 | AQ17: 0 | AR17: 0 | AS17: 0 | AT17: 0 | AU17: 0 | AV17: 0 | AW17: 0 | AX17: 0 | AY17: 0 | AZ17: 0 | BA17: 0 | BB17: 0 | BC17: 0 | BD17: 0 | BE17: 0 | BF17: 0 | BG17: 0 | BH17: 0 | BI17: 0 | BJ17: 0 | BK17: 0 | BL17: 0 | BM17: 0 | BN17: 0 | BO17: 0 | BP17: 0 | BQ17: 0 | BR17: 0 | BS17: 0 | BT17: 0 | BU17: 0 | BV17: 0 | BW17: 0 | BX17: 0 | BY17: 0 | BZ17: 0 | CA17: 0 | CB17: 0 | CC17: 0 | CD17: 0 | CE17: 0 | CF17: 0 | CG17: 0 | CH17: 0 | CI17: 0 | CJ17: 0 | CK17: 0 | CL17: 0 | CM17: 0 | CN17: 0 | CO17: 0 | CP17: 0 | CQ17: 0 | CR17: 0 | CS17: 0 | CT17: 0 | CU17: 0 | CV17: 0 | CW17: 0
A18: Medical Office | B18: 0.018155095 | C18: 0.027272217 | D18: 0.011789752 | E18: 0.0064709919 | F18: 0.00075012682 | G18: 0.0044843358 | H18: 0.014649818 | I18: 0.0014256544 | J18: 0.0061234947 | K18: 0.05144149 | L18: 0.0030282636 | M18: 0.021172173 | N18: 0.0032538277 | V18: 0 | W18: 0 | X18: 0 | Y18: 0 | Z18: 0 | AA18: 0 | AB18: 0 | AC18: 0 | AD18: 0 | AE18: 0 | AF18: 0 | AG18: 0 | AH18: 0 | AI18: 0 | AJ18: 0 | AK18: 0 | AL18: 0 | AM18: 0 | AN18: 0 | AO18: 0 | AP18: 0 | AQ18: 0 | AR18: 0 | AS18: 0 | AT18: 0 | AU18: 0 | AV18: 0 | AW18: 0 | AX18: 0 | AY18: 0 | AZ18: 0 | BA18: 0 | BB18: 0 | BC18: 0 | BD18: 0 | BE18: 0 | BF18: 0 | BG18: 0 | BH18: 0 | BI18: 0 | BJ18: 0 | BK18: 0 | BL18: 0 | BM18: 0 | BN18: 0 | BO18: 0 | BP18: 0 | BQ18: 0 | BR18: 0 | BS18: 0 | BT18: 0 | BU18: 0 | BV18: 0 | BW18: 0 | BX18: 0 | BY18: 0 | BZ18: 0 | CA18: 0 | CB18: 0 | CC18: 0 | CD18: 0 | CE18: 0 | CF18: 0 | CG18: 0 | CH18: 0 | CI18: 0 | CJ18: 0 | CK18: 0 | CL18: 0 | CM18: 0 | CN18: 0 | CO18: 0 | CP18: 0 | CQ18: 0 | CR18: 0 | CS18: 0 | CT18: 0 | CU18: 0 | CV18: 0 | CW18: 0
A19: Data Center | B19: 0.0026504499 | C19: 0.0019597948 | D19: 0.0044658519 | E19: 0.002807566 | F19: 0.00064461816 | G19: 0.0031605184 | H19: 0.0043931368 | I19: 0.00043174459 | J19: 0.0013444289 | K19: 0.0030282636 | L19: 0.0063516718 | M19: 0.0031173107 | N19: 0.00084817871 | V19: 0 | W19: 0 | X19: 0 | Y19: 0 | Z19: 0 | AA19: 0 | AB19: 0 | AC19: 0 | AD19: 0 | AE19: 0 | AF19: 0 | AG19: 0 | AH19: 0 | AI19: 0 | AJ19: 0 | AK19: 0 | AL19: 0 | AM19: 0 | AN19: 0 | AO19: 0 | AP19: 0 | AQ19: 0 | AR19: 0 | AS19: 0 | AT19: 0 | AU19: 0 | AV19: 0 | AW19: 0 | AX19: 0 | AY19: 0 | AZ19: 0 | BA19: 0 | BB19: 0 | BC19: 0 | BD19: 0 | BE19: 0 | BF19: 0 | BG19: 0 | BH19: 0 | BI19: 0 | BJ19: 0 | BK19: 0 | BL19: 0 | BM19: 0 | BN19: 0 | BO19: 0 | BP19: 0 | BQ19: 0 | BR19: 0 | BS19: 0 | BT19: 0 | BU19: 0 | BV19: 0 | BW19: 0 | BX19: 0 | BY19: 0 | BZ19: 0 | CA19: 0 | CB19: 0 | CC19: 0 | CD19: 0 | CE19: 0 | CF19: 0 | CG19: 0 | CH19: 0 | CI19: 0 | CJ19: 0 | CK19: 0 | CL19: 0 | CM19: 0 | CN19: 0 | CO19: 0 | CP19: 0 | CQ19: 0 | CR19: 0 | CS19: 0 | CT19: 0 | CU19: 0 | CV19: 0 | CW19: 0
A20: SFR | B20: 0.0056805481 | C20: 0.0073110452 | D20: 0.0073885304 | E20: 0.0040811974 | F20: 0.0020725215 | G20: 0.0046451498 | H20: 0.0071680878 | I20: 0.00088970069 | J20: 0.0032672045 | K20: 0.021172173 | L20: 0.0031173107 | M20: 0.009494324 | N20: 0.0019946254 | V20: 0 | W20: 0 | X20: 0 | Y20: 0 | Z20: 0 | AA20: 0 | AB20: 0 | AC20: 0 | AD20: 0 | AE20: 0 | AF20: 0 | AG20: 0 | AH20: 0 | AI20: 0 | AJ20: 0 | AK20: 0 | AL20: 0 | AM20: 0 | AN20: 0 | AO20: 0 | AP20: 0 | AQ20: 0 | AR20: 0 | AS20: 0 | AT20: 0 | AU20: 0 | AV20: 0 | AW20: 0 | AX20: 0 | AY20: 0 | AZ20: 0 | BA20: 0 | BB20: 0 | BC20: 0 | BD20: 0 | BE20: 0 | BF20: 0 | BG20: 0 | BH20: 0 | BI20: 0 | BJ20: 0 | BK20: 0 | BL20: 0 | BM20: 0 | BN20: 0 | BO20: 0 | BP20: 0 | BQ20: 0 | BR20: 0 | BS20: 0 | BT20: 0 | BU20: 0 | BV20: 0 | BW20: 0 | BX20: 0 | BY20: 0 | BZ20: 0 | CA20: 0 | CB20: 0 | CC20: 0 | CD20: 0 | CE20: 0 | CF20: 0 | CG20: 0 | CH20: 0 | CI20: 0 | CJ20: 0 | CK20: 0 | CL20: 0 | CM20: 0 | CN20: 0 | CO20: 0 | CP20: 0 | CQ20: 0 | CR20: 0 | CS20: 0 | CT20: 0 | CU20: 0 | CV20: 0 | CW20: 0
A21: Manufactured | B21: 0.0015681671 | C21: 0.0023317981 | D21: 0.0016774693 | E21: 0.0014471843 | F21: 0.00039534565 | G21: 0.0016129045 | H21: 0.00075940623 | I21: -0.00016514137 | J21: 0.00095671305 | K21: 0.0032538277 | L21: 0.00084817871 | M21: 0.0019946254 | N21: 0.0033369273 | V21: 0 | W21: 0 | X21: 0 | Y21: 0 | Z21: 0 | AA21: 0 | AB21: 0 | AC21: 0 | AD21: 0 | AE21: 0 | AF21: 0 | AG21: 0 | AH21: 0 | AI21: 0 | AJ21: 0 | AK21: 0 | AL21: 0 | AM21: 0 | AN21: 0 | AO21: 0 | AP21: 0 | AQ21: 0 | AR21: 0 | AS21: 0 | AT21: 0 | AU21: 0 | AV21: 0 | AW21: 0 | AX21: 0 | AY21: 0 | AZ21: 0 | BA21: 0 | BB21: 0 | BC21: 0 | BD21: 0 | BE21: 0 | BF21: 0 | BG21: 0 | BH21: 0 | BI21: 0 | BJ21: 0 | BK21: 0 | BL21: 0 | BM21: 0 | BN21: 0 | BO21: 0 | BP21: 0 | BQ21: 0 | BR21: 0 | BS21: 0 | BT21: 0 | BU21: 0 | BV21: 0 | BW21: 0 | BX21: 0 | BY21: 0 | BZ21: 0 | CA21: 0 | CB21: 0 | CC21: 0 | CD21: 0 | CE21: 0 | CF21: 0 | CG21: 0 | CH21: 0 | CI21: 0 | CJ21: 0 | CK21: 0 | CL21: 0 | CM21: 0 | CN21: 0 | CO21: 0 | CP21: 0 | CQ21: 0 | CR21: 0 | CS21: 0 | CT21: 0 | CU21: 0 | CV21: 0 | CW21: 0
V22: 0 | W22: 0 | X22: 0 | Y22: 0 | Z22: 0 | AA22: 0 | AB22: 0 | AC22: 0 | AD22: 0 | AE22: 0 | AF22: 0 | AG22: 0 | AH22: 0 | AI22: 0 | AJ22: 0 | AK22: 0 | AL22: 0 | AM22: 0 | AN22: 0 | AO22: 0 | AP22: 0 | AQ22: 0 | AR22: 0 | AS22: 0 | AT22: 0 | AU22: 0 | AV22: 0 | AW22: 0 | AX22: 0 | AY22: 0 | AZ22: 0 | BA22: 0 | BB22: 0 | BC22: 0 | BD22: 0 | BE22: 0 | BF22: 0 | BG22: 0 | BH22: 0 | BI22: 0 | BJ22: 0 | BK22: 0 | BL22: 0 | BM22: 0 | BN22: 0 | BO22: 0 | BP22: 0 | BQ22: 0 | BR22: 0 | BS22: 0 | BT22: 0 | BU22: 0 | BV22: 0 | BW22: 0 | BX22: 0 | BY22: 0 | BZ22: 0 | CA22: 0 | CB22: 0 | CC22: 0 | CD22: 0 | CE22: 0 | CF22: 0 | CG22: 0 | CH22: 0 | CI22: 0 | CJ22: 0 | CK22: 0 | CL22: 0 | CM22: 0 | CN22: 0 | CO22: 0 | CP22: 0 | CQ22: 0 | CR22: 0 | CS22: 0 | CT22: 0 | CU22: 0 | CV22: 0 | CW22: 0
V23: 0 | W23: 0 | X23: 0 | Y23: 0 | Z23: 0 | AA23: 0 | AB23: 0 | AC23: 0 | AD23: 0 | AE23: 0 | AF23: 0 | AG23: 0 | AH23: 0 | AI23: 0 | AJ23: 0 | AK23: 0 | AL23: 0 | AM23: 0 | AN23: 0 | AO23: 0 | AP23: 0 | AQ23: 0 | AR23: 0 | AS23: 0 | AT23: 0 | AU23: 0 | AV23: 0 | AW23: 0 | AX23: 0 | AY23: 0 | AZ23: 0 | BA23: 0 | BB23: 0 | BC23: 0 | BD23: 0 | BE23: 0 | BF23: 0 | BG23: 0 | BH23: 0 | BI23: 0 | BJ23: 0 | BK23: 0 | BL23: 0 | BM23: 0 | BN23: 0 | BO23: 0 | BP23: 0 | BQ23: 0 | BR23: 0 | BS23: 0 | BT23: 0 | BU23: 0 | BV23: 0 | BW23: 0 | BX23: 0 | BY23: 0 | BZ23: 0 | CA23: 0 | CB23: 0 | CC23: 0 | CD23: 0 | CE23: 0 | CF23: 0 | CG23: 0 | CH23: 0 | CI23: 0 | CJ23: 0 | CK23: 0 | CL23: 0 | CM23: 0 | CN23: 0 | CO23: 0 | CP23: 0 | CQ23: 0 | CR23: 0 | CS23: 0 | CT23: 0 | CU23: 0 | CV23: 0 | CW23: 0
V24: 0 | W24: 0 | X24: 0 | Y24: 0 | Z24: 0 | AA24: 0 | AB24: 0 | AC24: 0 | AD24: 0 | AE24: 0 | AF24: 0 | AG24: 0 | AH24: 0 | AI24: 0 | AJ24: 0 | AK24: 0 | AL24: 0 | AM24: 0 | AN24: 0 | AO24: 0 | AP24: 0 | AQ24: 0 | AR24: 0 | AS24: 0 | AT24: 0 | AU24: 0 | AV24: 0 | AW24: 0 | AX24: 0 | AY24: 0 | AZ24: 0 | BA24: 0 | BB24: 0 | BC24: 0 | BD24: 0 | BE24: 0 | BF24: 0 | BG24: 0 | BH24: 0 | BI24: 0 | BJ24: 0 | BK24: 0 | BL24: 0 | BM24: 0 | BN24: 0 | BO24: 0 | BP24: 0 | BQ24: 0 | BR24: 0 | BS24: 0 | BT24: 0 | BU24: 0 | BV24: 0 | BW24: 0 | BX24: 0 | BY24: 0 | BZ24: 0 | CA24: 0 | CB24: 0 | CC24: 0 | CD24: 0 | CE24: 0 | CF24: 0 | CG24: 0 | CH24: 0 | CI24: 0 | CJ24: 0 | CK24: 0 | CL24: 0 | CM24: 0 | CN24: 0 | CO24: 0 | CP24: 0 | CQ24: 0 | CR24: 0 | CS24: 0 | CT24: 0 | CU24: 0 | CV24: 0 | CW24: 0
V25: 0 | W25: 0 | X25: 0 | Y25: 0 | Z25: 0 | AA25: 0 | AB25: 0 | AC25: 0 | AD25: 0 | AE25: 0 | AF25: 0 | AG25: 0 | AH25: 0 | AI25: 0 | AJ25: 0 | AK25: 0 | AL25: 0 | AM25: 0 | AN25: 0 | AO25: 0 | AP25: 0 | AQ25: 0 | AR25: 0 | AS25: 0 | AT25: 0 | AU25: 0 | AV25: 0 | AW25: 0 | AX25: 0 | AY25: 0 | AZ25: 0 | BA25: 0 | BB25: 0 | BC25: 0 | BD25: 0 | BE25: 0 | BF25: 0 | BG25: 0 | BH25: 0 | BI25: 0 | BJ25: 0 | BK25: 0 | BL25: 0 | BM25: 0 | BN25: 0 | BO25: 0 | BP25: 0 | BQ25: 0 | BR25: 0 | BS25: 0 | BT25: 0 | BU25: 0 | BV25: 0 | BW25: 0 | BX25: 0 | BY25: 0 | BZ25: 0 | CA25: 0 | CB25: 0 | CC25: 0 | CD25: 0 | CE25: 0 | CF25: 0 | CG25: 0 | CH25: 0 | CI25: 0 | CJ25: 0 | CK25: 0 | CL25: 0 | CM25: 0 | CN25: 0 | CO25: 0 | CP25: 0 | CQ25: 0 | CR25: 0 | CS25: 0 | CT25: 0 | CU25: 0 | CV25: 0 | CW25: 0
V26: 0 | W26: 0 | X26: 0 | Y26: 0 | Z26: 0 | AA26: 0 | AB26: 0 | AC26: 0 | AD26: 0 | AE26: 0 | AF26: 0 | AG26: 0 | AH26: 0 | AI26: 0 | AJ26: 0 | AK26: 0 | AL26: 0 | AM26: 0 | AN26: 0 | AO26: 0 | AP26: 0 | AQ26: 0 | AR26: 0 | AS26: 0 | AT26: 0 | AU26: 0 | AV26: 0 | AW26: 0 | AX26: 0 | AY26: 0 | AZ26: 0 | BA26: 0 | BB26: 0 | BC26: 0 | BD26: 0 | BE26: 0 | BF26: 0 | BG26: 0 | BH26: 0 | BI26: 0 | BJ26: 0 | BK26: 0 | BL26: 0 | BM26: 0 | BN26: 0 | BO26: 0 | BP26: 0 | BQ26: 0 | BR26: 0 | BS26: 0 | BT26: 0 | BU26: 0 | BV26: 0 | BW26: 0 | BX26: 0 | BY26: 0 | BZ26: 0 | CA26: 0 | CB26: 0 | CC26: 0 | CD26: 0 | CE26: 0 | CF26: 0 | CG26: 0 | CH26: 0 | CI26: 0 | CJ26: 0 | CK26: 0 | CL26: 0 | CM26: 0 | CN26: 0 | CO26: 0 | CP26: 0 | CQ26: 0 | CR26: 0 | CS26: 0 | CT26: 0 | CU26: 0 | CV26: 0 | CW26: 0
V27: 0 | W27: 0 | X27: 0 | Y27: 0 | Z27: 0 | AA27: 0 | AB27: 0 | AC27: 0 | AD27: 0 | AE27: 0 | AF27: 0 | AG27: 0 | AH27: 0 | AI27: 0 | AJ27: 0 | AK27: 0 | AL27: 0 | AM27: 0 | AN27: 0 | AO27: 0 | AP27: 0 | AQ27: 0 | AR27: 0 | AS27: 0 | AT27: 0 | AU27: 0 | AV27: 0 | AW27: 0 | AX27: 0 | AY27: 0 | AZ27: 0 | BA27: 0 | BB27: 0 | BC27: 0 | BD27: 0 | BE27: 0 | BF27: 0 | BG27: 0 | BH27: 0 | BI27: 0 | BJ27: 0 | BK27: 0 | BL27: 0 | BM27: 0 | BN27: 0 | BO27: 0 | BP27: 0 | BQ27: 0 | BR27: 0 | BS27: 0 | BT27: 0 | BU27: 0 | BV27: 0 | BW27: 0 | BX27: 0 | BY27: 0 | BZ27: 0 | CA27: 0 | CB27: 0 | CC27: 0 | CD27: 0 | CE27: 0 | CF27: 0 | CG27: 0 | CH27: 0 | CI27: 0 | CJ27: 0 | CK27: 0 | CL27: 0 | CM27: 0 | CN27: 0 | CO27: 0 | CP27: 0 | CQ27: 0 | CR27: 0 | CS27: 0 | CT27: 0 | CU27: 0 | CV27: 0 | CW27: 0
V28: 0 | W28: 0 | X28: 0 | Y28: 0 | Z28: 0 | AA28: 0 | AB28: 0 | AC28: 0 | AD28: 0 | AE28: 0 | AF28: 0 | AG28: 0 | AH28: 0 | AI28: 0 | AJ28: 0 | AK28: 0 | AL28: 0 | AM28: 0 | AN28: 0 | AO28: 0 | AP28: 0 | AQ28: 0 | AR28: 0 | AS28: 0 | AT28: 0 | AU28: 0 | AV28: 0 | AW28: 0 | AX28: 0 | AY28: 0 | AZ28: 0 | BA28: 0 | BB28: 0 | BC28: 0 | BD28: 0 | BE28: 0 | BF28: 0 | BG28: 0 | BH28: 0 | BI28: 0 | BJ28: 0 | BK28: 0 | BL28: 0 | BM28: 0 | BN28: 0 | BO28: 0 | BP28: 0 | BQ28: 0 | BR28: 0 | BS28: 0 | BT28: 0 | BU28: 0 | BV28: 0 | BW28: 0 | BX28: 0 | BY28: 0 | BZ28: 0 | CA28: 0 | CB28: 0 | CC28: 0 | CD28: 0 | CE28: 0 | CF28: 0 | CG28: 0 | CH28: 0 | CI28: 0 | CJ28: 0 | CK28: 0 | CL28: 0 | CM28: 0 | CN28: 0 | CO28: 0 | CP28: 0 | CQ28: 0 | CR28: 0 | CS28: 0 | CT28: 0 | CU28: 0 | CV28: 0 | CW28: 0
V29: 1 | W29: 0 | X29: 0 | Y29: 0 | Z29: 0 | AA29: 0 | AB29: 0 | AC29: 0 | AD29: 0 | AE29: 0 | AF29: 0 | AG29: 0 | AH29: 0 | AI29: 0 | AJ29: 0 | AK29: 0 | AL29: 0 | AM29: 0 | AN29: 0 | AO29: 0 | AP29: 0 | AQ29: 0 | AR29: 0 | AS29: 0 | AT29: 0 | AU29: 0 | AV29: 0 | AW29: 0 | AX29: 0 | AY29: 0 | AZ29: 0 | BA29: 0 | BB29: 0 | BC29: 0 | BD29: 0 | BE29: 0 | BF29: 0 | BG29: 0 | BH29: 0 | BI29: 0 | BJ29: 0 | BK29: 0 | BL29: 0 | BM29: 0 | BN29: 0 | BO29: 0 | BP29: 0 | BQ29: 0 | BR29: 0 | BS29: 0 | BT29: 0 | BU29: 0 | BV29: 0 | BW29: 0 | BX29: 0 | BY29: 0 | BZ29: 0 | CA29: 0 | CB29: 0 | CC29: 0 | CD29: 0 | CE29: 0 | CF29: 0 | CG29: 0 | CH29: 0 | CI29: 0 | CJ29: 0 | CK29: 0 | CL29: 0 | CM29: 0 | CN29: 0 | CO29: 0 | CP29: 0 | CQ29: 0 | CR29: 0 | CS29: 0 | CT29: 0 | CU29: 0 | CV29: 0 | CW29: 0
V30: 0 | W30: 1 | X30: 0 | Y30: 0 | Z30: 0 | AA30: 0 | AB30: 0 | AC30: 0 | AD30: 0 | AE30: 0 | AF30: 0 | AG30: 0 | AH30: 0 | AI30: 0 | AJ30: 0 | AK30: 0 | AL30: 0 | AM30: 0 | AN30: 0 | AO30: 0 | AP30: 0 | AQ30: 0 | AR30: 0 | AS30: 0 | AT30: 0 | AU30: 0 | AV30: 0 | AW30: 0 | AX30: 0 | AY30: 0 | AZ30: 0 | BA30: 0 | BB30: 0 | BC30: 0 | BD30: 0 | BE30: 0 | BF30: 0 | BG30: 0 | BH30: 0 | BI30: 0 | BJ30: 0 | BK30: 0 | BL30: 0 | BM30: 0 | BN30: 0 | BO30: 0 | BP30: 0 | BQ30: 0 | BR30: 0 | BS30: 0 | BT30: 0 | BU30: 0 | BV30: 0 | BW30: 0 | BX30: 0 | BY30: 0 | BZ30: 0 | CA30: 0 | CB30: 0 | CC30: 0 | CD30: 0 | CE30: 0 | CF30: 0 | CG30: 0 | CH30: 0 | CI30: 0 | CJ30: 0 | CK30: 0 | CL30: 0 | CM30: 0 | CN30: 0 | CO30: 0 | CP30: 0 | CQ30: 0 | CR30: 0 | CS30: 0 | CT30: 0 | CU30: 0 | CV30: 0 | CW30: 0
V31: 0 | W31: 0 | X31: 1 | Y31: 0 | Z31: 0 | AA31: 0 | AB31: 0 | AC31: 0 | AD31: 0 | AE31: 0 | AF31: 0 | AG31: 0 | AH31: 0 | AI31: 0 | AJ31: 0 | AK31: 0 | AL31: 0 | AM31: 0 | AN31: 0 | AO31: 0 | AP31: 0 | AQ31: 0 | AR31: 0 | AS31: 0 | AT31: 0 | AU31: 0 | AV31: 0 | AW31: 0 | AX31: 0 | AY31: 0 | AZ31: 0 | BA31: 0 | BB31: 0 | BC31: 0 | BD31: 0 | BE31: 0 | BF31: 0 | BG31: 0 | BH31: 0 | BI31: 0 | BJ31: 0 | BK31: 0 | BL31: 0 | BM31: 0 | BN31: 0 | BO31: 0 | BP31: 0 | BQ31: 0 | BR31: 0 | BS31: 0 | BT31: 0 | BU31: 0 | BV31: 0 | BW31: 0 | BX31: 0 | BY31: 0 | BZ31: 0 | CA31: 0 | CB31: 0 | CC31: 0 | CD31: 0 | CE31: 0 | CF31: 0 | CG31: 0 | CH31: 0 | CI31: 0 | CJ31: 0 | CK31: 0 | CL31: 0 | CM31: 0 | CN31: 0 | CO31: 0 | CP31: 0 | CQ31: 0 | CR31: 0 | CS31: 0 | CT31: 0 | CU31: 0 | CV31: 0 | CW31: 0
V32: 0 | W32: 0 | X32: 0 | Y32: 1 | Z32: 0 | AA32: 0 | AB32: 0 | AC32: 0 | AD32: 0 | AE32: 0 | AF32: 0 | AG32: 0 | AH32: 0 | AI32: 0 | AJ32: 0 | AK32: 0 | AL32: 0 | AM32: 0 | AN32: 0 | AO32: 0 | AP32: 0 | AQ32: 0 | AR32: 0 | AS32: 0 | AT32: 0 | AU32: 0 | AV32: 0 | AW32: 0 | AX32: 0 | AY32: 0 | AZ32: 0 | BA32: 0 | BB32: 0 | BC32: 0 | BD32: 0 | BE32: 0 | BF32: 0 | BG32: 0 | BH32: 0 | BI32: 0 | BJ32: 0 | BK32: 0 | BL32: 0 | BM32: 0 | BN32: 0 | BO32: 0 | BP32: 0 | BQ32: 0 | BR32: 0 | BS32: 0 | BT32: 0 | BU32: 0 | BV32: 0 | BW32: 0 | BX32: 0 | BY32: 0 | BZ32: 0 | CA32: 0 | CB32: 0 | CC32: 0 | CD32: 0 | CE32: 0 | CF32: 0 | CG32: 0 | CH32: 0 | CI32: 0 | CJ32: 0 | CK32: 0 | CL32: 0 | CM32: 0 | CN32: 0 | CO32: 0 | CP32: 0 | CQ32: 0 | CR32: 0 | CS32: 0 | CT32: 0 | CU32: 0 | CV32: 0 | CW32: 0
V33: 0 | W33: 0 | X33: 0 | Y33: 0 | Z33: 1 | AA33: 0 | AB33: 0 | AC33: 0 | AD33: 0 | AE33: 0 | AF33: 0 | AG33: 0 | AH33: 0 | AI33: 0 | AJ33: 0 | AK33: 0 | AL33: 0 | AM33: 0 | AN33: 0 | AO33: 0 | AP33: 0 | AQ33: 0 | AR33: 0 | AS33: 0 | AT33: 0 | AU33: 0 | AV33: 0 | AW33: 0 | AX33: 0 | AY33: 0 | AZ33: 0 | BA33: 0 | BB33: 0 | BC33: 0 | BD33: 0 | BE33: 0 | BF33: 0 | BG33: 0 | BH33: 0 | BI33: 0 | BJ33: 0 | BK33: 0 | BL33: 0 | BM33: 0 | BN33: 0 | BO33: 0 | BP33: 0 | BQ33: 0 | BR33: 0 | BS33: 0 | BT33: 0 | BU33: 0 | BV33: 0 | BW33: 0 | BX33: 0 | BY33: 0 | BZ33: 0 | CA33: 0 | CB33: 0 | CC33: 0 | CD33: 0 | CE33: 0 | CF33: 0 | CG33: 0 | CH33: 0 | CI33: 0 | CJ33: 0 | CK33: 0 | CL33: 0 | CM33: 0 | CN33: 0 | CO33: 0 | CP33: 0 | CQ33: 0 | CR33: 0 | CS33: 0 | CT33: 0 | CU33: 0 | CV33: 0 | CW33: 0
... V108: 0 | W108: 0 | X108: 0 | Y108: 0 | Z108: 0 | AA108: 0 | AB108: 0 | AC108: 0 | AD108: 0 | AE108: 0 | AF108: 0 | AG108: 0 | AH108: 0 | AI108: 0 | AJ108: 0 | AK108: 0 | AL108: 0 | AM108: 0 | AN108: 0 | AO108: 0 | AP108: 0 | AQ108: 0 | AR108: 0 | AS108: 0 | AT108: 0 | AU108: 0 | AV108: 0 | AW108: 0 | AX108: 0 | AY108: 0 | AZ108: 0 | BA108: 0 | BB108: 0 | BC108: 0 | BD108: 0 | BE108: 0 | BF108: 0 | BG108: 0 | BH108: 0 | BI108: 0 | BJ108: 0 | BK108: 0 | BL108: 0 | BM108: 0 | BN108: 0 | BO108: 0 | BP108: 0 | BQ108: 0 | BR108: 0 | BS108: 0 | BT108: 0 | BU108: 0 | BV108: 0 | BW108: 0 | BX108: 0 | BY108: 0 | BZ108: 0 | CA108: 0 | CB108: 0 | CC108: 0 | CD108: 0 | CE108: 0 | CF108: 0 | CG108: 0 | CH108: 0 | CI108: 0 | CJ108: 0 | CK108: 0 | CL108: 0 | CM108: 0 | CN108: 0 | CO108: 0 | CP108: 0 | CQ108: 0 | CR108: 0 | CS108: 0 | CT108: 0 | CU108: 0 | CV108: 0 | CW108: 1
A110: MinWt | B110: 0 | C110: 0 | D110: 0 | E110: 0 | F110: 0 | G110: 0 | H110: 0 | I110: 0 | J110: 0 | K110: 0 | L110: 0 | M110: 0 | N110: 0 | O110: 0 | P110: 0 | Q110: 0 | R110: 0 | S110: 0 | T110: 0 | U110: 0 | V110: 0 | W110: 0 | X110: 0 | Y110: 0 | Z110: 0 | AA110: 0 | AB110: 0 | AC110: 0 | AD110: 0 | AE110: 0 | AF110: 0 | AG110: 0 | AH110: 0 | AI110: 0 | AJ110: 0 | AK110: 0 | AL110: 0 | AM110: 0 | AN110: 0 | AO110: 0 | AP110: 0 | AQ110: 0 | AR110: 0 | AS110: 0 | AT110: 0 | AU110: 0 | AV110: 0 | AW110: 0 | AX110: 0 | AY110: 0 | AZ110: 0 | BA110: 0 | BB110: 0 | BC110: 0 | BD110: 0 | BE110: 0 | BF110: 0 | BG110: 0 | BH110: 0 | BI110: 0 | BJ110: 0 | BK110: 0 | BL110: 0 | BM110: 0 | BN110: 0 | BO110: 0 | BP110: 0 | BQ110: 0 | BR110: 0 | BS110: 0 | BT110: 0 | BU110: 0 | BV110: 0 | BW110: 0 | BX110: 0 | BY110: 0 | BZ110: 0 | CA110: 0 | CB110: 0 | CC110: 0 | CD110: 0 | CE110: 0 | CF110: 0 | CG110: 0 | CH110: 0 | CI110: 0 | CJ110: 0 | CK110: 0 | CL110: 0 | CM110: 0 | CN110: 0 | CO110: 0 | CP110: 0 | CQ110: 0 | CR110: 0 | CS110: 0 | CT110: 0 | CU110: 0 | CV110: 0 | CW110: 0
A111: MaxWt | B111: 1 | C111: 1 | D111: 1 | E111: 1 | F111: 1 | G111: 1 | H111: 1 | I111: 1 | J111: 1 | K111: 1 | L111: 1 | M111: 1 | N111: 1 | O111: 1 | P111: 1 | Q111: 1 | R111: 1 | S111: 1 | T111: 1 | U111: 1 | V111: 1 | W111: 1 | X111: 1 | Y111: 1 | Z111: 1 | AA111: 1 | AB111: 1 | AC111: 1 | AD111: 1 | AE111: 1 | AF111: 1 | AG111: 1 | AH111: 1 | AI111: 1 | AJ111: 1 | AK111: 1 | AL111: 1 | AM111: 1 | AN111: 1 | AO111: 1 | AP111: 1 | AQ111: 1 | AR111: 1 | AS111: 1 | AT111: 1 | AU111: 1 | AV111: 1 | AW111: 1 | AX111: 1 | AY111: 1 | AZ111: 1 | BA111: 1 | BB111: 1 | BC111: 1 | BD111: 1 | BE111: 1 | BF111: 1 | BG111: 1 | BH111: 1 | BI111: 1 | BJ111: 1 | BK111: 1 | BL111: 1 | BM111: 1 | BN111: 1 | BO111: 1 | BP111: 1 | BQ111: 1 | BR111: 1 | BS111: 1 | BT111: 1 | BU111: 1 | BV111: 1 | BW111: 1 | BX111: 1 | BY111: 1 | BZ111: 1 | CA111: 1 | CB111: 1 | CC111: 1 | CD111: 1 | CE111: 1 | CF111: 1 | CG111: 1 | CH111: 1 | CI111: 1 | CJ111: 1 | CK111: 1 | CL111: 1 | CM111: 1 | CN111: 1 | CO111: 1 | CP111: 1 | CQ111: 1 | CR111: 1 | CS111: 1 | CT111: 1 | CU111: 1 | CV111: 1 | CW111: 1
A113: Risk free rate | B113: 0.042

Sheet Covariance Matrix
B1: Apartment | C1: Industrial | D1: Office | E1: Retail | F1: Data Center | G1: Hotel | H1: Life Science | I1: Manufactured | J1: Medical Office | K1: SFR | L1: Seniors | M1: Storage | N1: Student
A2: Apartment | B2: =_xlfn.COVARIANCE.S(INDIRECT("'" & $A2 & "'!K7:K86"), INDIRECT("'" & B$1 & "'!K7:K86"))*4 -> 0.007064145 | C2: =_xlfn.COVARIANCE.S(INDIRECT("'" & $A2 & "'!K7:K86"), INDIRECT("'" & C$1 & "'!K7:K86"))*4 -> 0.007851763 | D2: =_xlfn.COVARIANCE.S(INDIRECT("'" & $A2 & "'!K7:K86"), INDIRECT("'" & D$1 & "'!K7:K86"))*4 -> 0.0085357734 | E2: =_xlfn.COVARIANCE.S(INDIRECT("'" & $A2 & "'!K7:K86"), INDIRECT("'" & E$1 & "'!K7:K86"))*4 -> 0.0049623101 | F2: =_xlfn.COVARIANCE.S(INDIRECT("'" & $A2 & "'!K7:K86"), INDIRECT("'" & F$1 & "'!K7:K86"))*4 -> 0.0027196365 | G2: =_xlfn.COVARIANCE.S(INDIRECT("'" & $A2 & "'!K7:K86"), INDIRECT("'" & G$1 & "'!K7:K86"))*4 -> 0.0045531987 | H2: =_xlfn.COVARIANCE.S(INDIRECT("'" & $A2 & "'!K7:K86"), INDIRECT("'" & H$1 & "'!K7:K86"))*4 -> 0.0071024148 | I2: =_xlfn.COVARIANCE.S(INDIRECT("'" & $A2 & "'!K7:K86"), INDIRECT("'" & I$1 & "'!K7:K86"))*4 -> 0.00046230569 | ... N2: =_xlfn.COVARIANCE.S(INDIRECT("'" & $A2 & "'!K7:K86"), INDIRECT("'" & N$1 & "'!K7:K86"))*4 -> 0.0015681671
A3: Industrial | B3: =_xlfn.COVARIANCE.S(INDIRECT("'" & $A3 & "'!K7:K86"), INDIRECT("'" & B$1 & "'!K7:K86"))*4 -> 0.007851763 | C3: =_xlfn.COVARIANCE.S(INDIRECT("'" & $A3 & "'!K7:K86"), INDIRECT("'" & C$1 & "'!K7:K86"))*4 -> 0.01201099 | D3: =_xlfn.COVARIANCE.S(INDIRECT("'" & $A3 & "'!K7:K86"), INDIRECT("'" & D$1 & "'!K7:K86"))*4 -> 0.010018157 | E3: =_xlfn.COVARIANCE.S(INDIRECT("'" & $A3 & "'!K7:K86"), INDIRECT("'" & E$1 & "'!K7:K86"))*4 -> 0.0055227877 | F3: =_xlfn.COVARIANCE.S(INDIRECT("'" & $A3 & "'!K7:K86"), INDIRECT("'" & F$1 & "'!K7:K86"))*4 -> 0.0049702057 | G3: =_xlfn.COVARIANCE.S(INDIRECT("'" & $A3 & "'!K7:K86"), INDIRECT("'" & G$1 & "'!K7:K86"))*4 -> 0.0059860244 | H3: =_xlfn.COVARIANCE.S(INDIRECT("'" & $A3 & "'!K7:K86"), INDIRECT("'" & H$1 & "'!K7:K86"))*4 -> 0.0088730471 | I3: =_xlfn.COVARIANCE.S(INDIRECT("'" & $A3 & "'!K7:K86"), INDIRECT("'" & I$1 & "'!K7:K86"))*4 -> -0.0013667762 | ... N3: =_xlfn.COVARIANCE.S(INDIRECT("'" & $A3 & "'!K7:K86"), INDIRECT("'" & N$1 & "'!K7:K86"))*4 -> 0.0023317981
A4: Office | B4: =_xlfn.COVARIANCE.S(INDIRECT("'" & $A4 & "'!K7:K86"), INDIRECT("'" & B$1 & "'!K7:K86"))*4 -> 0.0085357734 | C4: =_xlfn.COVARIANCE.S(INDIRECT("'" & $A4 & "'!K7:K86"), INDIRECT("'" & C$1 & "'!K7:K86"))*4 -> 0.010018157 | D4: =_xlfn.COVARIANCE.S(INDIRECT("'" & $A4 & "'!K7:K86"), INDIRECT("'" & D$1 & "'!K7:K86"))*4 -> 0.015178771 | E4: =_xlfn.COVARIANCE.S(INDIRECT("'" & $A4 & "'!K7:K86"), INDIRECT("'" & E$1 & "'!K7:K86"))*4 -> 0.0073510272 | F4: =_xlfn.COVARIANCE.S(INDIRECT("'" & $A4 & "'!K7:K86"), INDIRECT("'" & F$1 & "'!K7:K86"))*4 -> 0.00387677 | G4: =_xlfn.COVARIANCE.S(INDIRECT("'" & $A4 & "'!K7:K86"), INDIRECT("'" & G$1 & "'!K7:K86"))*4 -> 0.0090860404 | H4: =_xlfn.COVARIANCE.S(INDIRECT("'" & $A4 & "'!K7:K86"), INDIRECT("'" & H$1 & "'!K7:K86"))*4 -> 0.01192322 | I4: =_xlfn.COVARIANCE.S(INDIRECT("'" & $A4 & "'!K7:K86"), INDIRECT("'" & I$1 & "'!K7:K86"))*4 -> -0.0023767155 | ... N4: =_xlfn.COVARIANCE.S(INDIRECT("'" & $A4 & "'!K7:K86"), INDIRECT("'" & N$1 & "'!K7:K86"))*4 -> 0.0016774693
A5: Retail | B5: =_xlfn.COVARIANCE.S(INDIRECT("'" & $A5 & "'!K7:K86"), INDIRECT("'" & B$1 & "'!K7:K86"))*4 -> 0.0049623101 | C5: =_xlfn.COVARIANCE.S(INDIRECT("'" & $A5 & "'!K7:K86"), INDIRECT("'" & C$1 & "'!K7:K86"))*4 -> 0.0055227877 | D5: =_xlfn.COVARIANCE.S(INDIRECT("'" & $A5 & "'!K7:K86"), INDIRECT("'" & D$1 & "'!K7:K86"))*4 -> 0.0073510272 | E5: =_xlfn.COVARIANCE.S(INDIRECT("'" & $A5 & "'!K7:K86"), INDIRECT("'" & E$1 & "'!K7:K86"))*4 -> 0.006753492 | F5: =_xlfn.COVARIANCE.S(INDIRECT("'" & $A5 & "'!K7:K86"), INDIRECT("'" & F$1 & "'!K7:K86"))*4 -> 0.0019150966 | G5: =_xlfn.COVARIANCE.S(INDIRECT("'" & $A5 & "'!K7:K86"), INDIRECT("'" & G$1 & "'!K7:K86"))*4 -> 0.0057577756 | H5: =_xlfn.COVARIANCE.S(INDIRECT("'" & $A5 & "'!K7:K86"), INDIRECT("'" & H$1 & "'!K7:K86"))*4 -> 0.0045886265 | I5: =_xlfn.COVARIANCE.S(INDIRECT("'" & $A5 & "'!K7:K86"), INDIRECT("'" & I$1 & "'!K7:K86"))*4 -> -0.00041258292 | ... N5: =_xlfn.COVARIANCE.S(INDIRECT("'" & $A5 & "'!K7:K86"), INDIRECT("'" & N$1 & "'!K7:K86"))*4 -> 0.0014471843
A6: Data Center | B6: =_xlfn.COVARIANCE.S(INDIRECT("'" & $A6 & "'!K7:K86"), INDIRECT("'" & B$1 & "'!K7:K86"))*4 -> 0.0027196365 | C6: =_xlfn.COVARIANCE.S(INDIRECT("'" & $A6 & "'!K7:K86"), INDIRECT("'" & C$1 & "'!K7:K86"))*4 -> 0.0049702057 | D6: =_xlfn.COVARIANCE.S(INDIRECT("'" & $A6 & "'!K7:K86"), INDIRECT("'" & D$1 & "'!K7:K86"))*4 -> 0.00387677 | E6: =_xlfn.COVARIANCE.S(INDIRECT("'" & $A6 & "'!K7:K86"), INDIRECT("'" & E$1 & "'!K7:K86"))*4 -> 0.0019150966 | F6: =_xlfn.COVARIANCE.S(INDIRECT("'" & $A6 & "'!K7:K86"), INDIRECT("'" & F$1 & "'!K7:K86"))*4 -> 0.0037950063 | G6: =_xlfn.COVARIANCE.S(INDIRECT("'" & $A6 & "'!K7:K86"), INDIRECT("'" & G$1 & "'!K7:K86"))*4 -> 0.00055901584 | H6: =_xlfn.COVARIANCE.S(INDIRECT("'" & $A6 & "'!K7:K86"), INDIRECT("'" & H$1 & "'!K7:K86"))*4 -> 0.0027234563 | I6: =_xlfn.COVARIANCE.S(INDIRECT("'" & $A6 & "'!K7:K86"), INDIRECT("'" & I$1 & "'!K7:K86"))*4 -> 0.00016463137 | ... N6: =_xlfn.COVARIANCE.S(INDIRECT("'" & $A6 & "'!K7:K86"), INDIRECT("'" & N$1 & "'!K7:K86"))*4 -> 0.00039534565
A7: Hotel | B7: =_xlfn.COVARIANCE.S(INDIRECT("'" & $A7 & "'!K7:K86"), INDIRECT("'" & B$1 & "'!K7:K86"))*4 -> 0.0045531987 | C7: =_xlfn.COVARIANCE.S(INDIRECT("'" & $A7 & "'!K7:K86"), INDIRECT("'" & C$1 & "'!K7:K86"))*4 -> 0.0059860244 | D7: =_xlfn.COVARIANCE.S(INDIRECT("'" & $A7 & "'!K7:K86"), INDIRECT("'" & D$1 & "'!K7:K86"))*4 -> 0.0090860404 | E7: =_xlfn.COVARIANCE.S(INDIRECT("'" & $A7 & "'!K7:K86"), INDIRECT("'" & E$1 & "'!K7:K86"))*4 -> 0.0057577756 | F7: =_xlfn.COVARIANCE.S(INDIRECT("'" & $A7 & "'!K7:K86"), INDIRECT("'" & F$1 & "'!K7:K86"))*4 -> 0.00055901584 | G7: =_xlfn.COVARIANCE.S(INDIRECT("'" & $A7 & "'!K7:K86"), INDIRECT("'" & G$1 & "'!K7:K86"))*4 -> 0.017522045 | H7: =_xlfn.COVARIANCE.S(INDIRECT("'" & $A7 & "'!K7:K86"), INDIRECT("'" & H$1 & "'!K7:K86"))*4 -> 0.010078023 | I7: =_xlfn.COVARIANCE.S(INDIRECT("'" & $A7 & "'!K7:K86"), INDIRECT("'" & I$1 & "'!K7:K86"))*4 -> 0.00029746545 | ... N7: =_xlfn.COVARIANCE.S(INDIRECT("'" & $A7 & "'!K7:K86"), INDIRECT("'" & N$1 & "'!K7:K86"))*4 -> 0.0016129045
A8: Life Science | B8: =_xlfn.COVARIANCE.S(INDIRECT("'" & $A8 & "'!K7:K86"), INDIRECT("'" & B$1 & "'!K7:K86"))*4 -> 0.0071024148 | C8: =_xlfn.COVARIANCE.S(INDIRECT("'" & $A8 & "'!K7:K86"), INDIRECT("'" & C$1 & "'!K7:K86"))*4 -> 0.0088730471 | D8: =_xlfn.COVARIANCE.S(INDIRECT("'" & $A8 & "'!K7:K86"), INDIRECT("'" & D$1 & "'!K7:K86"))*4 -> 0.01192322 | E8: =_xlfn.COVARIANCE.S(INDIRECT("'" & $A8 & "'!K7:K86"), INDIRECT("'" & E$1 & "'!K7:K86"))*4 -> 0.0045886265 | F8: =_xlfn.COVARIANCE.S(INDIRECT("'" & $A8 & "'!K7:K86"), INDIRECT("'" & F$1 & "'!K7:K86"))*4 -> 0.0027234563 | G8: =_xlfn.COVARIANCE.S(INDIRECT("'" & $A8 & "'!K7:K86"), INDIRECT("'" & G$1 & "'!K7:K86"))*4 -> 0.010078023 | H8: =_xlfn.COVARIANCE.S(INDIRECT("'" & $A8 & "'!K7:K86"), INDIRECT("'" & H$1 & "'!K7:K86"))*4 -> 0.023769561 | I8: =_xlfn.COVARIANCE.S(INDIRECT("'" & $A8 & "'!K7:K86"), INDIRECT("'" & I$1 & "'!K7:K86"))*4 -> 0.00011728729 | ... N8: =_xlfn.COVARIANCE.S(INDIRECT("'" & $A8 & "'!K7:K86"), INDIRECT("'" & N$1 & "'!K7:K86"))*4 -> 0.00075940623
A9: Manufactured | B9: =_xlfn.COVARIANCE.S(INDIRECT("'" & $A9 & "'!K7:K86"), INDIRECT("'" & B$1 & "'!K7:K86"))*4 -> 0.00046230569 | C9: =_xlfn.COVARIANCE.S(INDIRECT("'" & $A9 & "'!K7:K86"), INDIRECT("'" & C$1 & "'!K7:K86"))*4 -> -0.0013667762 | D9: =_xlfn.COVARIANCE.S(INDIRECT("'" & $A9 & "'!K7:K86"), INDIRECT("'" & D$1 & "'!K7:K86"))*4 -> -0.0023767155 | E9: =_xlfn.COVARIANCE.S(INDIRECT("'" & $A9 & "'!K7:K86"), INDIRECT("'" & E$1 & "'!K7:K86"))*4 -> -0.00041258292 | F9: =_xlfn.COVARIANCE.S(INDIRECT("'" & $A9 & "'!K7:K86"), INDIRECT("'" & F$1 & "'!K7:K86"))*4 -> 0.00016463137 | G9: =_xlfn.COVARIANCE.S(INDIRECT("'" & $A9 & "'!K7:K86"), INDIRECT("'" & G$1 & "'!K7:K86"))*4 -> 0.00029746545 | H9: =_xlfn.COVARIANCE.S(INDIRECT("'" & $A9 & "'!K7:K86"), INDIRECT("'" & H$1 & "'!K7:K86"))*4 -> 0.00011728729 | I9: =_xlfn.COVARIANCE.S(INDIRECT("'" & $A9 & "'!K7:K86"), INDIRECT("'" & I$1 & "'!K7:K86"))*4 -> 0.0061557656 | ... N9: =_xlfn.COVARIANCE.S(INDIRECT("'" & $A9 & "'!K7:K86"), INDIRECT("'" & N$1 & "'!K7:K86"))*4 -> -0.00016514137
A10: Medical Office | B10: =_xlfn.COVARIANCE.S(INDIRECT("'" & $A10 & "'!K7:K86"), INDIRECT("'" & B$1 & "'!K7:K86"))*4 -> 0.0038791356 | C10: =_xlfn.COVARIANCE.S(INDIRECT("'" & $A10 & "'!K7:K86"), INDIRECT("'" & C$1 & "'!K7:K86"))*4 -> 0.0051033043 | D10: =_xlfn.COVARIANCE.S(INDIRECT("'" & $A10 & "'!K7:K86"), INDIRECT("'" & D$1 & "'!K7:K86"))*4 -> 0.0072373684 | E10: =_xlfn.COVARIANCE.S(INDIRECT("'" & $A10 & "'!K7:K86"), INDIRECT("'" & E$1 & "'!K7:K86"))*4 -> 0.0030545714 | F10: =_xlfn.COVARIANCE.S(INDIRECT("'" & $A10 & "'!K7:K86"), INDIRECT("'" & F$1 & "'!K7:K86"))*4 -> 0.0015169414 | G10: =_xlfn.COVARIANCE.S(INDIRECT("'" & $A10 & "'!K7:K86"), INDIRECT("'" & G$1 & "'!K7:K86"))*4 -> 0.0069534921 | H10: =_xlfn.COVARIANCE.S(INDIRECT("'" & $A10 & "'!K7:K86"), INDIRECT("'" & H$1 & "'!K7:K86"))*4 -> 0.0056350079 | I10: =_xlfn.COVARIANCE.S(INDIRECT("'" & $A10 & "'!K7:K86"), INDIRECT("'" & I$1 & "'!K7:K86"))*4 -> 0.00033006543 | ... N10: =_xlfn.COVARIANCE.S(INDIRECT("'" & $A10 & "'!K7:K86"), INDIRECT("'" & N$1 & "'!K7:K86"))*4 -> 0.00095671305
A11: SFR | B11: =_xlfn.COVARIANCE.S(INDIRECT("'" & $A11 & "'!K7:K86"), INDIRECT("'" & B$1 & "'!K7:K86"))*4 -> 0.018155095 | C11: =_xlfn.COVARIANCE.S(INDIRECT("'" & $A11 & "'!K7:K86"), INDIRECT("'" & C$1 & "'!K7:K86"))*4 -> 0.027272217 | D11: =_xlfn.COVARIANCE.S(INDIRECT("'" & $A11 & "'!K7:K86"), INDIRECT("'" & D$1 & "'!K7:K86"))*4 -> 0.011789752 | E11: =_xlfn.COVARIANCE.S(INDIRECT("'" & $A11 & "'!K7:K86"), INDIRECT("'" & E$1 & "'!K7:K86"))*4 -> 0.0064709919 | F11: =_xlfn.COVARIANCE.S(INDIRECT("'" & $A11 & "'!K7:K86"), INDIRECT("'" & F$1 & "'!K7:K86"))*4 -> 0.00075012682 | G11: =_xlfn.COVARIANCE.S(INDIRECT("'" & $A11 & "'!K7:K86"), INDIRECT("'" & G$1 & "'!K7:K86"))*4 -> 0.0044843358 | H11: =_xlfn.COVARIANCE.S(INDIRECT("'" & $A11 & "'!K7:K86"), INDIRECT("'" & H$1 & "'!K7:K86"))*4 -> 0.014649818 | I11: =_xlfn.COVARIANCE.S(INDIRECT("'" & $A11 & "'!K7:K86"), INDIRECT("'" & I$1 & "'!K7:K86"))*4 -> 0.0014256544 | ... N11: =_xlfn.COVARIANCE.S(INDIRECT("'" & $A11 & "'!K7:K86"), INDIRECT("'" & N$1 & "'!K7:K86"))*4 -> 0.0032538277
A12: Seniors | B12: =_xlfn.COVARIANCE.S(INDIRECT("'" & $A12 & "'!K7:K86"), INDIRECT("'" & B$1 & "'!K7:K86"))*4 -> 0.0026504499 | C12: =_xlfn.COVARIANCE.S(INDIRECT("'" & $A12 & "'!K7:K86"), INDIRECT("'" & C$1 & "'!K7:K86"))*4 -> 0.0019597948 | D12: =_xlfn.COVARIANCE.S(INDIRECT("'" & $A12 & "'!K7:K86"), INDIRECT("'" & D$1 & "'!K7:K86"))*4 -> 0.0044658519 | E12: =_xlfn.COVARIANCE.S(INDIRECT("'" & $A12 & "'!K7:K86"), INDIRECT("'" & E$1 & "'!K7:K86"))*4 -> 0.002807566 | F12: =_xlfn.COVARIANCE.S(INDIRECT("'" & $A12 & "'!K7:K86"), INDIRECT("'" & F$1 & "'!K7:K86"))*4 -> 0.00064461816 | G12: =_xlfn.COVARIANCE.S(INDIRECT("'" & $A12 & "'!K7:K86"), INDIRECT("'" & G$1 & "'!K7:K86"))*4 -> 0.0031605184 | H12: =_xlfn.COVARIANCE.S(INDIRECT("'" & $A12 & "'!K7:K86"), INDIRECT("'" & H$1 & "'!K7:K86"))*4 -> 0.0043931368 | I12: =_xlfn.COVARIANCE.S(INDIRECT("'" & $A12 & "'!K7:K86"), INDIRECT("'" & I$1 & "'!K7:K86"))*4 -> 0.00043174459 | ... N12: =_xlfn.COVARIANCE.S(INDIRECT("'" & $A12 & "'!K7:K86"), INDIRECT("'" & N$1 & "'!K7:K86"))*4 -> 0.00084817871
A13: Storage | B13: =_xlfn.COVARIANCE.S(INDIRECT("'" & $A13 & "'!K7:K86"), INDIRECT("'" & B$1 & "'!K7:K86"))*4 -> 0.0056805481 | C13: =_xlfn.COVARIANCE.S(INDIRECT("'" & $A13 & "'!K7:K86"), INDIRECT("'" & C$1 & "'!K7:K86"))*4 -> 0.0073110452 | D13: =_xlfn.COVARIANCE.S(INDIRECT("'" & $A13 & "'!K7:K86"), INDIRECT("'" & D$1 & "'!K7:K86"))*4 -> 0.0073885304 | E13: =_xlfn.COVARIANCE.S(INDIRECT("'" & $A13 & "'!K7:K86"), INDIRECT("'" & E$1 & "'!K7:K86"))*4 -> 0.0040811974 | F13: =_xlfn.COVARIANCE.S(INDIRECT("'" & $A13 & "'!K7:K86"), INDIRECT("'" & F$1 & "'!K7:K86"))*4 -> 0.0020725215 | G13: =_xlfn.COVARIANCE.S(INDIRECT("'" & $A13 & "'!K7:K86"), INDIRECT("'" & G$1 & "'!K7:K86"))*4 -> 0.0046451498 | H13: =_xlfn.COVARIANCE.S(INDIRECT("'" & $A13 & "'!K7:K86"), INDIRECT("'" & H$1 & "'!K7:K86"))*4 -> 0.0071680878 | I13: =_xlfn.COVARIANCE.S(INDIRECT("'" & $A13 & "'!K7:K86"), INDIRECT("'" & I$1 & "'!K7:K86"))*4 -> 0.00088970069 | ... N13: =_xlfn.COVARIANCE.S(INDIRECT("'" & $A13 & "'!K7:K86"), INDIRECT("'" & N$1 & "'!K7:K86"))*4 -> 0.0019946254
A14: Student | B14: =_xlfn.COVARIANCE.S(INDIRECT("'" & $A14 & "'!K7:K86"), INDIRECT("'" & B$1 & "'!K7:K86"))*4 -> 0.0015681671 | C14: =_xlfn.COVARIANCE.S(INDIRECT("'" & $A14 & "'!K7:K86"), INDIRECT("'" & C$1 & "'!K7:K86"))*4 -> 0.0023317981 | D14: =_xlfn.COVARIANCE.S(INDIRECT("'" & $A14 & "'!K7:K86"), INDIRECT("'" & D$1 & "'!K7:K86"))*4 -> 0.0016774693 | E14: =_xlfn.COVARIANCE.S(INDIRECT("'" & $A14 & "'!K7:K86"), INDIRECT("'" & E$1 & "'!K7:K86"))*4 -> 0.0014471843 | F14: =_xlfn.COVARIANCE.S(INDIRECT("'" & $A14 & "'!K7:K86"), INDIRECT("'" & F$1 & "'!K7:K86"))*4 -> 0.00039534565 | G14: =_xlfn.COVARIANCE.S(INDIRECT("'" & $A14 & "'!K7:K86"), INDIRECT("'" & G$1 & "'!K7:K86"))*4 -> 0.0016129045 | H14: =_xlfn.COVARIANCE.S(INDIRECT("'" & $A14 & "'!K7:K86"), INDIRECT("'" & H$1 & "'!K7:K86"))*4 -> 0.00075940623 | I14: =_xlfn.COVARIANCE.S(INDIRECT("'" & $A14 & "'!K7:K86"), INDIRECT("'" & I$1 & "'!K7:K86"))*4 -> -0.00016514137 | ... N14: =_xlfn.COVARIANCE.S(INDIRECT("'" & $A14 & "'!K7:K86"), INDIRECT("'" & N$1 & "'!K7:K86"))*4 -> 0.0033369273

Sheet Summary
B2: Property Type | C2: Observed Volatility | D2: Desmoothed Volatility | E2: Periods Observed
B3: Apartment | C3: =+Apartment!F4 -> 0.055844423 | D3: =+Apartment!M4 -> 0.084048468 | E3: 80 | G3: {=(PRODUCT(_xlfn._xlws.FILTER(INDIRECT("'" & B3 & "'!K7:K86") + 1, ISNUMBER(INDIRECT("'" & B3 & "'!K7:K86")))) ^ (1 / (COUNTA(INDIRECT("'" & B3 & "'!K7:K86")) / 4))) - 1} -> 0.065552443
B4: Industrial | C4: =+Industrial!F4 -> 0.065625507 | D4: =+Industrial!M4 -> 0.10959466 | E4: 80 | G4: {=(PRODUCT(_xlfn._xlws.FILTER(INDIRECT("'" & B4 & "'!K7:K86") + 1, ISNUMBER(INDIRECT("'" & B4 & "'!K7:K86")))) ^ (1 / (COUNTA(INDIRECT("'" & B4 & "'!K7:K86")) / 4))) - 1} -> 0.10138031
B5: Office | C5: =+Office!F4 -> 0.062188163 | D5: =+Office!M4 -> 0.12320215 | E5: 80 | G5: {=(PRODUCT(_xlfn._xlws.FILTER(INDIRECT("'" & B5 & "'!K7:K86") + 1, ISNUMBER(INDIRECT("'" & B5 & "'!K7:K86")))) ^ (1 / (COUNTA(INDIRECT("'" & B5 & "'!K7:K86")) / 4))) - 1} -> 0.03431678
B6: Retail | C6: =+Retail!F4 -> 0.04464846 | D6: =+Retail!M4 -> 0.082179632 | E6: 80 | G6: {=(PRODUCT(_xlfn._xlws.FILTER(INDIRECT("'" & B6 & "'!K7:K86") + 1, ISNUMBER(INDIRECT("'" & B6 & "'!K7:K86")))) ^ (1 / (COUNTA(INDIRECT("'" & B6 & "'!K7:K86")) / 4))) - 1} -> 0.055641768
B7: Seniors | C7: =+Seniors!F4 -> 0.061521606 | D7: =+Seniors!M4 -> 0.079697376 | E7: 80 | G7: {=(PRODUCT(_xlfn._xlws.FILTER(INDIRECT("'" & B7 & "'!K7:K86") + 1, ISNUMBER(INDIRECT("'" & B7 & "'!K7:K86")))) ^ (1 / (COUNTA(INDIRECT("'" & B7 & "'!K7:K86")) / 4))) - 1} -> 0.099732922
B8: Storage | C8: =+Storage!F4 -> 0.063757336 | D8: =+Storage!M4 -> 0.097438822 | E8: 78 | G8: {=(PRODUCT(_xlfn._xlws.FILTER(INDIRECT("'" & B8 & "'!K7:K86") + 1, ISNUMBER(INDIRECT("'" & B8 & "'!K7:K86")))) ^ (1 / (COUNTA(INDIRECT("'" & B8 & "'!K7:K86")) / 4))) - 1} -> 0.11256441
B9: Life Science | C9: =+'Life Science'!F4 -> 0.084101628 | D9: =+'Life Science'!M4 -> 0.1541738 | E9: 77 | G9: {=(PRODUCT(_xlfn._xlws.FILTER(INDIRECT("'" & B9 & "'!K7:K86") + 1, ISNUMBER(INDIRECT("'" & B9 & "'!K7:K86")))) ^ (1 / (COUNTA(INDIRECT("'" & B9 & "'!K7:K86")) / 4))) - 1} -> 0.09340312
B10: Hotel | C10: =+Hotel!F4 -> 0.078523533 | D10: =+Hotel!M4 -> 0.13237086 | E10: 75 | G10: {=(PRODUCT(_xlfn._xlws.FILTER(INDIRECT("'" & B10 & "'!K7:K86") + 1, ISNUMBER(INDIRECT("'" & B10 & "'!K7:K86")))) ^ (1 / (COUNTA(INDIRECT("'" & B10 & "'!K7:K86")) / 4))) - 1} -> 0.044260049
B11: Student | C11: =+Student!F4 -> 0.049061736 | D11: =+Storage!M4 -> 0.097438822 | E11: 69 | G11: {=(PRODUCT(_xlfn._xlws.FILTER(INDIRECT("'" & B11 & "'!K7:K86") + 1, ISNUMBER(INDIRECT("'" & B11 & "'!K7:K86")))) ^ (1 / (COUNTA(INDIRECT("'" & B11 & "'!K7:K86")) / 4))) - 1} -> 0.059025678
B12: Medical Office | C12: =+'Medical Office'!F4 -> 0.044749377 | D12: =+'Medical Office'!M4 -> 0.089113231 | E12: 67 | G12: {=(PRODUCT(_xlfn._xlws.FILTER(INDIRECT("'" & B12 & "'!K7:K86") + 1, ISNUMBER(INDIRECT("'" & B12 & "'!K7:K86")))) ^ (1 / (COUNTA(INDIRECT("'" & B12 & "'!K7:K86")) / 4))) - 1} -> 0.050263474
B13: Data Center | C13: =+'Data Center'!F4 -> 0.039474835 | D13: =+'Data Center'!M4 -> 0.061603622 | E13: 23 | G13: {=(PRODUCT(_xlfn._xlws.FILTER(INDIRECT("'" & B13 & "'!K7:K86") + 1, ISNUMBER(INDIRECT("'" & B13 & "'!K7:K86")))) ^ (1 / (COUNTA(INDIRECT("'" & B13 & "'!K7:K86")) / 4))) - 1} -> 0.097754626
B14: SFR | C14: =+SFR!F4 -> 0.10315875 | D14: =+SFR!M4 -> 0.22680716 | E14: 14 | G14: {=(PRODUCT(_xlfn._xlws.FILTER(INDIRECT("'" & B14 & "'!K7:K86") + 1, ISNUMBER(INDIRECT("'" & B14 & "'!K7:K86")))) ^ (1 / (COUNTA(INDIRECT("'" & B14 & "'!K7:K86")) / 4))) - 1} -> 0.076541481
B15: Manufactured | C15: =+Manufactured!F4 -> 0.032507491 | D15: =+Manufactured!M4 -> 0.078458687 | E15: 12 | G15: {=(PRODUCT(_xlfn._xlws.FILTER(INDIRECT("'" & B15 & "'!K7:K86") + 1, ISNUMBER(INDIRECT("'" & B15 & "'!K7:K86")))) ^ (1 / (COUNTA(INDIRECT("'" & B15 & "'!K7:K86")) / 4))) - 1} -> 0.090157905

Sheet Apartment
A1: Property Type: | C1: Apartment
A2: Autocorrelation Coefficient: | C2: =CORREL(C7:C86,C9:C88) -> 0.6015374
F3: Observed Volatility | M3: Demsoothed Volatility
F4: {=+(STDEV(D7:D86+1)*SQRT(4))} -> 0.055844423 | M4: {=+(STDEV(K7:K86+1)*SQRT(4))} -> 0.084048468
B5: Observed Returns | I5: Desmoothed Returns
B6: INC | C6: APP | D6: TGRS | I6: INC | J6: APP | K6: TGRS | M6: {=(PRODUCT(1 + K7:K86)^(1/20)) - 1} -> 0.065552443
A7: 20244 | B7: 0.0109 | C7: 0.0007 | D7: 0.0117 | I7: =+B7 -> 0.0109 | J7: =(C7-($C$2*C8))/(1-$C$2) -> 0.0023606104 | K7: =(1+I7)*(1+J7)-1 -> 0.013286341
A8: 20243 | B8: 0.0111 | C8: -0.0004 | D8: 0.0107 | I8: =+B8 -> 0.0111 | J8: =(C8-($C$2*C9))/(1-$C$2) -> 0.014847423 | K8: =(1+I8)*(1+J8)-1 -> 0.026112229
A9: 20242 | B9: 0.0111 | C9: -0.0105 | D9: 0.0006 | I9: =+B9 -> 0.0111 | J9: =(C9-($C$2*C10))/(1-$C$2) -> 0.0052003162 | K9: =(1+I9)*(1+J9)-1 -> 0.01635804
A10: 20241 | B10: 0.0106 | C10: -0.0209 | D10: -0.0103 | I10: =+B10 -> 0.0106 | J10: =(C10-($C$2*C11))/(1-$C$2) -> 0.010047739 | K10: =(1+I10)*(1+J10)-1 -> 0.020754245
A11: 20234 | B11: 0.0104 | C11: -0.0414 | D11: -0.031 | I11: =+B11 -> 0.0104 | J11: =(C11-($C$2*C12))/(1-$C$2) -> -0.066913014 | K11: =(1+I11)*(1+J11)-1 -> -0.057208909
A12: 20233 | B12: 0.0099 | C12: -0.0245 | D12: -0.0146 | I12: =+B12 -> 0.0099 | J12: =(C12-($C$2*C13))/(1-$C$2) -> -0.029934725 | K12: =(1+I12)*(1+J12)-1 -> -0.020331079
A13: 20232 | B13: 0.0098 | C13: -0.0209 | D13: -0.0111 | I13: =+B13 -> 0.0098 | J13: =(C13-($C$2*C14))/(1-$C$2) -> -0.0059545066 | K13: =(1+I13)*(1+J13)-1 -> 0.0037871392
A14: 20231 | B14: 0.0095 | C14: -0.0308 | D14: -0.0213 | I14: =+B14 -> 0.0095 | J14: =(C14-($C$2*C15))/(1-$C$2) -> -0.015854507 | K14: =(1+I14)*(1+J14)-1 -> -0.0065051245
A15: 20224 | B15: 0.0091 | C15: -0.0407 | D15: -0.0316 | I15: =+B15 -> 0.0091 | J15: =(C15-($C$2*C16))/(1-$C$2) -> -0.10712441 | K15: =(1+I15)*(1+J15)-1 -> -0.098999247
A16: 20223 | B16: 0.009 | C16: 0.0033 | D16: 0.0123 | I16: =+B16 -> 0.009 | J16: =(C16-($C$2*C17))/(1-$C$2) -> -0.035648861 | K16: =(1+I16)*(1+J16)-1 -> -0.026969701
A17: 20222 | B17: 0.0092 | C17: 0.0291 | D17: 0.0383 | I17: =+B17 -> 0.0092 | J17: =(C17-($C$2*C18))/(1-$C$2) -> 0.0079649589 | K17: =(1+I17)*(1+J17)-1 -> 0.017238237
A18: 20221 | B18: 0.0093 | C18: 0.0431 | D18: 0.0524 | I18: =+B18 -> 0.0093 | J18: =(C18-($C$2*C19))/(1-$C$2) -> 0.018945667 | K18: =(1+I18)*(1+J18)-1 -> 0.028421862
... A194: 19781 | B194: 0.0203 | C194: 0.0113 | D194: 0.0316 | I194: =+B194 -> 0.0203 | J194: =(C194-($C$2*C195))/(1-$C$2) -> 0.028358997 | K194: =(1+I194)*(1+J194)-1 -> 0.049234685

Sheet Industrial
A1: Property Type: | C1: Industrial
A2: Autocorrelation Coefficient: | C2: =CORREL(C7:C86,C9:C88) -> 0.64660393
F3: Observed Volatility | M3: Demsoothed Volatility
F4: {=+(STDEV(D7:D86+1)*SQRT(4))} -> 0.065625507 | M4: {=+(STDEV(K7:K86+1)*SQRT(4))} -> 0.10959466
B5: Observed Returns | I5: Desmoothed Returns
B6: INC | C6: APP | D6: TGRS | I6: INC | J6: APP | K6: TGRS
A7: 20244 | B7: 0.0098 | C7: 0.0019 | D7: 0.0117 | I7: =+B7 -> 0.0098 | J7: =(C7-($C$2*C8))/(1-$C$2) -> 0.0039126549 | K7: =(1+I7)*(1+J7)-1 -> 0.013750999
A8: 20243 | B8: 0.01 | C8: 0.0008 | D8: 0.0108 | I8: =+B8 -> 0.01 | J8: =(C8-($C$2*C9))/(1-$C$2) -> 0.016535302 | K8: =(1+I8)*(1+J8)-1 -> 0.026700655
A9: 20242 | B9: 0.0098 | C9: -0.0078 | D9: 0.002 | I9: =+B9 -> 0.0098 | J9: =(C9-($C$2*C10))/(1-$C$2) -> -0.0067021882 | K9: =(1+I9)*(1+J9)-1 -> 0.0030321303
A10: 20241 | B10: 0.0096 | C10: -0.0084 | D10: 0.0013 | I10: =+B10 -> 0.0096 | J10: =(C10-($C$2*C11))/(1-$C$2) -> 0.034963565 | K10: =(1+I10)*(1+J10)-1 -> 0.044899215
A11: 20234 | B11: 0.0092 | C11: -0.0321 | D11: -0.0229 | I11: =+B11 -> 0.0092 | J11: =(C11-($C$2*C12))/(1-$C$2) -> -0.069974506 | K11: =(1+I11)*(1+J11)-1 -> -0.061418271
A12: 20233 | B12: 0.0088 | C12: -0.0114 | D12: -0.0026 | I12: =+B12 -> 0.0088 | J12: =(C12-($C$2*C13))/(1-$C$2) -> -0.0029834432 | K12: =(1+I12)*(1+J12)-1 -> 0.0057903025
A13: 20232 | B13: 0.0086 | C13: -0.016 | D13: -0.0074 | I13: =+B13 -> 0.0086 | J13: =(C13-($C$2*C14))/(1-$C$2) -> -0.015268125 | K13: =(1+I13)*(1+J13)-1 -> -0.0067994314
A14: 20231 | B14: 0.0084 | C14: -0.0164 | D14: -0.0081 | I14: =+B14 -> 0.0084 | J14: =(C14-($C$2*C15))/(1-$C$2) -> 0.032635592 | K14: =(1+I14)*(1+J14)-1 -> 0.041309731
A15: 20224 | B15: 0.0077 | C15: -0.0432 | D15: -0.0355 | I15: =+B15 -> 0.0077 | J15: =(C15-($C$2*C16))/(1-$C$2) -> -0.12864635 | K15: =(1+I15)*(1+J15)-1 -> -0.12193693
A16: 20223 | B16: 0.0076 | C16: 0.0035 | D16: 0.0112 | I16: =+B16 -> 0.0076 | J16: =(C16-($C$2*C17))/(1-$C$2) -> -0.083410098 | K16: =(1+I16)*(1+J16)-1 -> -0.076444015
A17: 20222 | B17: 0.0078 | C17: 0.051 | D17: 0.0588 | I17: =+B17 -> 0.0078 | J17: =(C17-($C$2*C18))/(1-$C$2) -> -0.040484314 | K17: =(1+I17)*(1+J17)-1 -> -0.033000091
A18: 20221 | B18: 0.0084 | C18: 0.101 | D18: 0.1094 | I18: =+B18 -> 0.0084 | J18: =(C18-($C$2*C19))/(1-$C$2) -> 0.059283153 | K18: =(1+I18)*(1+J18)-1 -> 0.068181132
... A194: 19781 | B194: 0.0212 | C194: 0.0094 | D194: 0.0305 | I194: =+B194 -> 0.0212 | J194: =(C194-($C$2*C195))/(1-$C$2) -> 0.026599051 | K194: =(1+I194)*(1+J194)-1 -> 0.048362951

Sheet Office
A1: Property Type: | C1: Office
A2: Autocorrelation Coefficient: | C2: =CORREL(C7:C86,C9:C88) -> 0.74465112
F3: Observed Volatility | M3: Demsoothed Volatility
F4: {=+(STDEV(D7:D86+1)*SQRT(4))} -> 0.062188163 | M4: {=+(STDEV(K7:K86+1)*SQRT(4))} -> 0.12320215
B5: Observed Returns | I5: Desmoothed Returns
B6: INC | C6: APP | D6: TGRS | I6: INC | J6: APP | K6: TGRS
A7: 20244 | B7: 0.0146 | C7: -0.0216 | D7: -0.0071 | I7: =+B7 -> 0.0146 | J7: =(C7-($C$2*C8))/(1-$C$2) -> -0.010810021 | K7: =(1+I7)*(1+J7)-1 -> 0.003632153
A8: 20243 | B8: 0.0148 | C8: -0.0253 | D8: -0.0106 | I8: =+B8 -> 0.0148 | J8: =(C8-($C$2*C9))/(1-$C$2) -> 0.01319398 | K8: =(1+I8)*(1+J8)-1 -> 0.028189251
A9: 20242 | B9: 0.0148 | C9: -0.0385 | D9: -0.0236 | I9: =+B9 -> 0.0148 | J9: =(C9-($C$2*C10))/(1-$C$2) -> 0.0020353276 | K9: =(1+I9)*(1+J9)-1 -> 0.01686545
A10: 20241 | B10: 0.0144 | C10: -0.0524 | D10: -0.038 | I10: =+B10 -> 0.0144 | J10: =(C10-($C$2*C11))/(1-$C$2) -> -0.0092400829 | K10: =(1+I10)*(1+J10)-1 -> 0.0050268599
A11: 20234 | B11: 0.0132 | C11: -0.0672 | D11: -0.0539 | I11: =+B11 -> 0.0132 | J11: =(C11-($C$2*C12))/(1-$C$2) -> -0.11735882 | K11: =(1+I11)*(1+J11)-1 -> -0.10570796
A12: 20233 | B12: 0.013 | C12: -0.05 | D12: -0.037 | I12: =+B12 -> 0.013 | J12: =(C12-($C$2*C13))/(1-$C$2) -> 0.0086158334 | K12: =(1+I12)*(1+J12)-1 -> 0.021727839
A13: 20232 | B13: 0.0122 | C13: -0.0701 | D13: -0.0579 | I13: =+B13 -> 0.0122 | J13: =(C13-($C$2*C14))/(1-$C$2) -> -0.12230017 | K13: =(1+I13)*(1+J13)-1 -> -0.11159223
A14: 20231 | B14: 0.0114 | C14: -0.0522 | D14: -0.0408 | I14: =+B14 -> 0.0114 | J14: =(C14-($C$2*C15))/(1-$C$2) -> -0.034119494 | K14: =(1+I14)*(1+J14)-1 -> -0.023108456
A15: 20224 | B15: 0.0106 | C15: -0.0584 | D15: -0.0478 | I15: =+B15 -> 0.0106 | J15: =(C15-($C$2*C16))/(1-$C$2) -> -0.17825626 | K15: =(1+I15)*(1+J15)-1 -> -0.16954577
A16: 20223 | B16: 0.0104 | C16: -0.0173 | D16: -0.0069 | I16: =+B16 -> 0.0104 | J16: =(C16-($C$2*C17))/(1-$C$2) -> -0.053169391 | K16: =(1+I16)*(1+J16)-1 -> -0.043322352
A17: 20222 | B17: 0.0108 | C17: -0.005 | D17: 0.0058 | I17: =+B17 -> 0.0108 | J17: =(C17-($C$2*C18))/(1-$C$2) -> -0.038244801 | K17: =(1+I17)*(1+J17)-1 -> -0.027857845
A18: 20221 | B18: 0.0106 | C18: 0.0064 | D18: 0.017 | I18: =+B18 -> 0.0106 | J18: =(C18-($C$2*C19))/(1-$C$2) -> 0.0081497264 | K18: =(1+I18)*(1+J18)-1 -> 0.018836113
... A194: 19781 | B194: 0.0226 | C194: 0.0018 | D194: 0.0245 | I194: =+B194 -> 0.0226 | J194: =(C194-($C$2*C195))/(1-$C$2) -> 0.0070491791 | K194: =(1+I194)*(1+J194)-1 -> 0.029808491

Sheet Retail
A1: Property Type: | C1: Retail
A2: Autocorrelation Coefficient: | C2: =CORREL(C7:C86,C9:C88) -> 0.66379439
F3: Observed Volatility | M3: Demsoothed Volatility
F4: {=+(STDEV(D7:D86+1)*SQRT(4))} -> 0.04464846 | M4: {=+(STDEV(K7:K86+1)*SQRT(4))} -> 0.082179632
B5: Observed Returns | I5: Desmoothed Returns
B6: INC | C6: APP | D6: TGRS | I6: INC | J6: APP | K6: TGRS
A7: 20244 | B7: 0.0139 | C7: 0.0047 | D7: 0.0186 | I7: =+B7 -> 0.0139 | J7: =(C7-($C$2*C8))/(1-$C$2) -> 0.004502563 | K7: =(1+I7)*(1+J7)-1 -> 0.018465149
A8: 20243 | B8: 0.0137 | C8: 0.0048 | D8: 0.0185 | I8: =+B8 -> 0.0137 | J8: =(C8-($C$2*C9))/(1-$C$2) -> 0.022766771 | K8: =(1+I8)*(1+J8)-1 -> 0.036778675
A9: 20242 | B9: 0.0133 | C9: -0.0043 | D9: 0.009 | I9: =+B9 -> 0.0133 | J9: =(C9-($C$2*C10))/(1-$C$2) -> 0.0020179852 | K9: =(1+I9)*(1+J9)-1 -> 0.015344824
A10: 20241 | B10: 0.0138 | C10: -0.0075 | D10: 0.0062 | I10: =+B10 -> 0.0138 | J10: =(C10-($C$2*C11))/(1-$C$2) -> 0.027248919 | K10: =(1+I10)*(1+J10)-1 -> 0.041424954
A11: 20234 | B11: 0.0133 | C11: -0.0251 | D11: -0.0118 | I11: =+B11 -> 0.0133 | J11: =(C11-($C$2*C12))/(1-$C$2) -> -0.047212948 | K11: =(1+I11)*(1+J11)-1 -> -0.034540881
A12: 20233 | B12: 0.0128 | C12: -0.0139 | D12: -0.0011 | I12: =+B12 -> 0.0128 | J12: =(C12-($C$2*C13))/(1-$C$2) -> -0.013110252 | K12: =(1+I12)*(1+J12)-1 -> -0.00047806307
A13: 20232 | B13: 0.0127 | C13: -0.0143 | D13: -0.0016 | I13: =+B13 -> 0.0127 | J13: =(C13-($C$2*C14))/(1-$C$2) -> -0.027133408 | K13: =(1+I13)*(1+J13)-1 -> -0.014778002
A14: 20231 | B14: 0.0129 | C14: -0.0078 | D14: 0.0052 | I14: =+B14 -> 0.0129 | J14: =(C14-($C$2*C15))/(1-$C$2) -> 0.032279719 | K14: =(1+I14)*(1+J14)-1 -> 0.045596127
A15: 20224 | B15: 0.0125 | C15: -0.0281 | D15: -0.0156 | I15: =+B15 -> 0.0125 | J15: =(C15-($C$2*C16))/(1-$C$2) -> -0.067982282 | K15: =(1+I15)*(1+J15)-1 -> -0.05633206
A16: 20223 | B16: 0.0119 | C16: -0.0079 | D16: 0.004 | I16: =+B16 -> 0.0119 | J16: =(C16-($C$2*C17))/(1-$C$2) -> -0.031987319 | K16: =(1+I16)*(1+J16)-1 -> -0.020467968
A17: 20222 | B17: 0.0125 | C17: 0.0043 | D17: 0.0168 | I17: =+B17 -> 0.0125 | J17: =(C17-($C$2*C18))/(1-$C$2) -> -0.0035974816 | K17: =(1+I17)*(1+J17)-1 -> 0.0088575499
A18: 20221 | B18: 0.0122 | C18: 0.0083 | D18: 0.0205 | I18: =+B18 -> 0.0122 | J18: =(C18-($C$2*C19))/(1-$C$2) -> 0.0063256296 | K18: =(1+I18)*(1+J18)-1 -> 0.018602802
... A194: 19781 | B194: 0.0205 | C194: 0.0073 | D194: 0.0278 | I194: =+B194 -> 0.0205 | J194: =(C194-($C$2*C195))/(1-$C$2) -> 0.021712904 | K194: =(1+I194)*(1+J194)-1 -> 0.042658018

Sheet Data Center
A1: Property Type: | C1: Data Center
A2: Autocorrelation Coefficient: | C2: =CORREL(C7:C27,C9:C29) -> 0.35923676
F3: Observed Volatility | M3: Demsoothed Volatility
F4: =STDEV(D7:D29)*SQRT(4) -> 0.039474835 | M4: =STDEV(K7:K29)*SQRT(4) -> 0.061603622
B5: Observed Returns | I5: Desmoothed Returns
B6: INC | C6: APP | D6: TGRS | I6: INC | J6: APP | K6: TGRS
A7: 20244 | B7: 0.0074 | C7: 0.018 | D7: 0.0253 | I7: =+B7 -> 0.0074 | J7: =(C7-($C$2*C8))/(1-$C$2) -> -0.0012859765 | K7: =(1+I7)*(1+J7)-1 -> 0.0061045073
A8: 20243 | B8: 0.0035 | C8: 0.0524 | D8: 0.0559 | I8: =+B8 -> 0.0035 | J8: =(C8-($C$2*C9))/(1-$C$2) -> 0.085477692 | K8: =(1+I8)*(1+J8)-1 -> 0.089276864
A9: 20242 | B9: 0.0084 | C9: -0.0066 | D9: 0.0019 | I9: =+B9 -> 0.0084 | J9: =(C9-($C$2*C10))/(1-$C$2) -> -0.018821927 | K9: =(1+I9)*(1+J9)-1 -> -0.010580031
A10: 20241 | B10: 0.0112 | C10: 0.0152 | D10: 0.0265 | I10: =+B10 -> 0.0112 | J10: =(C10-($C$2*C11))/(1-$C$2) -> 0.028991716 | K10: =(1+I10)*(1+J10)-1 -> 0.040516423
A11: 20234 | B11: 0.0121 | C11: -0.0094 | D11: 0.0027 | I11: =+B11 -> 0.0121 | J11: =(C11-($C$2*C12))/(1-$C$2) -> -0.012875961 | K11: =(1+I11)*(1+J11)-1 -> -0.00093176
A12: 20233 | B12: 0.0104 | C12: -0.0032 | D12: 0.0071 | I12: =+B12 -> 0.0104 | J12: =(C12-($C$2*C13))/(1-$C$2) -> -0.0034242555 | K12: =(1+I12)*(1+J12)-1 -> 0.0069401322
A13: 20232 | B13: 0.011 | C13: -0.0028 | D13: 0.0082 | I13: =+B13 -> 0.011 | J13: =(C13-($C$2*C14))/(1-$C$2) -> -0.0060517053 | K13: =(1+I13)*(1+J13)-1 -> 0.0048817259
A14: 20231 | B14: 0.0111 | C14: 0.003 | D14: 0.0141 | I14: =+B14 -> 0.0111 | J14: =(C14-($C$2*C15))/(1-$C$2) -> 0.021669274 | K14: =(1+I14)*(1+J14)-1 -> 0.033009803
A15: 20224 | B15: 0.0109 | C15: -0.0303 | D15: -0.0194 | I15: =+B15 -> 0.0109 | J15: =(C15-($C$2*C16))/(1-$C$2) -> -0.050426935 | K15: =(1+I15)*(1+J15)-1 -> -0.040076588
A16: 20223 | B16: 0.0106 | C16: 0.0056 | D16: 0.0163 | I16: =+B16 -> 0.0106 | J16: =(C16-($C$2*C17))/(1-$C$2) -> 0.0077304276 | K16: =(1+I16)*(1+J16)-1 -> 0.01841237
A17: 20222 | B17: 0.0131 | C17: 0.0018 | D17: 0.0149 | I17: =+B17 -> 0.0131 | J17: =(C17-($C$2*C18))/(1-$C$2) -> -0.009412777 | K17: =(1+I17)*(1+J17)-1 -> 0.0035639156
A18: 20221 | B18: 0.0125 | C18: 0.0218 | D18: 0.0343 | I18: =+B18 -> 0.0125 | J18: =(C18-($C$2*C19))/(1-$C$2) -> 0.031274797 | K18: =(1+I18)*(1+J18)-1 -> 0.044165732
... A29: 20192 | B29: 0.0075 | C29: 0.0083 | D29: 0.0158 | I29: =+B29 -> 0.0075 | J29: =(C29-($C$2*C30))/(1-$C$2) -> 0.012953302 | K29: =(1+I29)*(1+J29)-1 -> 0.020550452

Sheet Hotel
A1: Property Type: | C1: Hotel
A2: Autocorrelation Coefficient: | C2: =CORREL(C7:C79,C9:C81) -> 0.45714725
F3: Observed Volatility | M3: Demsoothed Volatility
F4: {=+(STDEV(D7:D81+1)*SQRT(4))} -> 0.078523533 | M4: {=+(STDEV(K7:K81+1)*SQRT(4))} -> 0.13237086
B5: Observed Returns | I5: Desmoothed Returns
B6: INC | C6: APP | D6: TGRS | I6: INC | J6: APP | K6: TGRS
A7: 20244 | B7: 0.0184 | C7: -0.0095 | D7: 0.0089 | I7: =+B7 -> 0.0184 | J7: =(C7-($C$2*C8))/(1-$C$2) -> -0.021879166 | K7: =(1+I7)*(1+J7)-1 -> -0.003881743
A8: 20243 | B8: 0.0223 | C8: 0.0052 | D8: 0.0275 | I8: =+B8 -> 0.0223 | J8: =(C8-($C$2*C9))/(1-$C$2) -> 0.0079789965 | K8: =(1+I8)*(1+J8)-1 -> 0.030456928
A9: 20242 | B9: 0.0187 | C9: 0.0019 | D9: 0.0206 | I9: =+B9 -> 0.0187 | J9: =(C9-($C$2*C10))/(1-$C$2) -> 0.0054369047 | K9: =(1+I9)*(1+J9)-1 -> 0.024238575
A10: 20241 | B10: 0.0107 | C10: -0.0023 | D10: 0.0084 | I10: =+B10 -> 0.0107 | J10: =(C10-($C$2*C11))/(1-$C$2) -> -0.0033947562 | K10: =(1+I10)*(1+J10)-1 -> 0.0072689199
A11: 20234 | B11: 0.0189 | C11: -0.001 | D11: 0.0179 | I11: =+B11 -> 0.0189 | J11: =(C11-($C$2*C12))/(1-$C$2) -> 9.4756205e-05 | K11: =(1+I11)*(1+J11)-1 -> 0.018996547
A12: 20233 | B12: 0.0211 | C12: -0.0023 | D12: 0.0188 | I12: =+B12 -> 0.0211 | J12: =(C12-($C$2*C13))/(1-$C$2) -> -0.020489795 | K12: =(1+I12)*(1+J12)-1 -> 0.00017786991
A13: 20232 | B13: 0.0189 | C13: 0.0193 | D13: 0.0382 | I13: =+B13 -> 0.0189 | J13: =(C13-($C$2*C14))/(1-$C$2) -> 0.022752693 | K13: =(1+I13)*(1+J13)-1 -> 0.042082719
A14: 20231 | B14: 0.0077 | C14: 0.0152 | D14: 0.0229 | I14: =+B14 -> 0.0077 | J14: =(C14-($C$2*C15))/(1-$C$2) -> 0.017978997 | K14: =(1+I14)*(1+J14)-1 -> 0.025817435
A15: 20224 | B15: 0.0206 | C15: 0.0119 | D15: 0.0325 | I15: =+B15 -> 0.0206 | J15: =(C15-($C$2*C16))/(1-$C$2) -> 0.019142233 | K15: =(1+I15)*(1+J15)-1 -> 0.040136563
A16: 20223 | B16: 0.0239 | C16: 0.0033 | D16: 0.0271 | I16: =+B16 -> 0.0239 | J16: =(C16-($C$2*C17))/(1-$C$2) -> 0.0054053004 | K16: =(1+I16)*(1+J16)-1 -> 0.029434487
A17: 20222 | B17: 0.0154 | C17: 0.0008 | D17: 0.0162 | I17: =+B17 -> 0.0154 | J17: =(C17-($C$2*C18))/(1-$C$2) -> -0.015116071 | K17: =(1+I17)*(1+J17)-1 -> 5.1141524e-05
